Workbook
Name BRA: 'Currencies & CETs'!$B$4
Name cet_BRA_hi: 'Currencies & CETs'!$I$4
Name cet_BRA_lo: 'Currencies & CETs'!$H$4
Name cet_BRA_Woods: 'Currencies & CETs'!#REF!
Name cet_IND_hi: 'Currencies & CETs'!$I$15
Name cet_IND_lo: 'Currencies & CETs'!$H$15
Name cet_IND_Woods: 'Currencies & CETs'!#REF!
Name cet_ZAF_hi: 'Currencies & CETs'!$I$26
Name cet_ZAF_lo: 'Currencies & CETs'!$H$26
Name cet_ZAF_Woods: 'Currencies & CETs'!#REF!
Name IND: 'Currencies & CETs'!$B$15
Name ZAF: 'Currencies & CETs'!$B$26

Sheet ceasumm_raw_results (260519)
B1: iso | C1: intv | D1: run | E1: c_Int | F1: DALY | G1: QALY | H1: Inc_costs | I1: DALY_avert | J1: QALY_gains | K1: ICERs | L1: NB_low | M1: NB_high | O1: Mean cost | P1: Median cost | Q1: 2.5% cost | R1: 97.5% cost | S1: Med incr cost | T1: Mean DALY | U1: Median DALY | V1: 2.5% DALY | W1: 97.5% DALY | Y1: < lower Och CET? | Z1: < upper Och CET? | AA1: % CE at low Och CET | AB1: % CE at high Och CET | AC1: version 2: | AD1: < lower Och CET? | AE1: < upper Och CET? | AF1: % CE at low Och CET | AG1: % CE at high Och CET | AI1: Low mismatch | AJ1: High mismatch | AL1: c_Int<0 | AM1: % c_Int<0
A2: 1 | B2: BRA | C2: BAU | D2: 1 | E2: 1.9136745e+09 | F2: 6718255.7 | G2: 4.4891806e+09 | H2: 0 | I2: 0 | J2: 0 | K2: NA | L2: 0 | M2: 0 | O2: =AVERAGE(E2:E501) -> 1.6111629e+09 | P2: =_xlfn.PERCENTILE.INC(E2:E501,0.5) -> 1.5685268e+09 | Q2: =_xlfn.PERCENTILE.INC(E2:E501,0.025) -> 9.9586562e+08 | R2: =_xlfn.PERCENTILE.INC(E2:E501,0.975) -> 2.3960757e+09 | S2: =_xlfn.PERCENTILE.INC(H2:H501,0.5) -> 0 | T2: =AVERAGE(F2:F501) -> 6489723.6 | U2: =_xlfn.PERCENTILE.INC(F2:F501,0.5) -> 6494616.6 | V2: =_xlfn.PERCENTILE.INC(F2:F501,0.025) -> 5742336.3 | W2: =_xlfn.PERCENTILE.INC(F2:F501,0.975) -> 7190390.5 | AL2: =IF(H2<0,1,0) -> 0 | AM2: =AVERAGE(AL2:AL501) -> 0
A3: 2 | B3: BRA | C3: BAU | D3: 2 | E3: 1.4550541e+09 | F3: 6987005.2 | G3: 4.4891184e+09 | H3: 0 | I3: 0 | J3: 0 | K3: NA | L3: 0 | M3: 0 | AL3: =IF(H3<0,1,0) -> 0
A4: 3 | B4: BRA | C4: BAU | D4: 3 | E4: 1.6038309e+09 | F4: 6212602 | G4: 4.4870468e+09 | H4: 0 | I4: 0 | J4: 0 | K4: NA | L4: 0 | M4: 0 | AL4: =IF(H4<0,1,0) -> 0
A5: 4 | B5: BRA | C5: BAU | D5: 4 | E5: 1.7068068e+09 | F5: 6415317.8 | G5: 4.4897824e+09 | H5: 0 | I5: 0 | J5: 0 | K5: NA | L5: 0 | M5: 0 | AL5: =IF(H5<0,1,0) -> 0
A6: 5 | B6: BRA | C6: BAU | D6: 5 | E6: 1.367878e+09 | F6: 6033101.9 | G6: 4.486885e+09 | H6: 0 | I6: 0 | J6: 0 | K6: NA | L6: 0 | M6: 0 | AL6: =IF(H6<0,1,0) -> 0
A7: 6 | B7: BRA | C7: BAU | D7: 6 | E7: 1.2222035e+09 | F7: 6237820.6 | G7: 4.4871295e+09 | H7: 0 | I7: 0 | J7: 0 | K7: NA | L7: 0 | M7: 0 | AL7: =IF(H7<0,1,0) -> 0
A8: 7 | B8: BRA | C8: BAU | D8: 7 | E8: 1.4188236e+09 | F8: 6281229.2 | G8: 4.4880226e+09 | H8: 0 | I8: 0 | J8: 0 | K8: NA | L8: 0 | M8: 0 | AL8: =IF(H8<0,1,0) -> 0
A9: 8 | B9: BRA | C9: BAU | D9: 8 | E9: 1.6469556e+09 | F9: 6708784.9 | G9: 4.491034e+09 | H9: 0 | I9: 0 | J9: 0 | K9: NA | L9: 0 | M9: 0 | AL9: =IF(H9<0,1,0) -> 0
A10: 9 | B10: BRA | C10: BAU | D10: 9 | E10: 2.6006574e+09 | F10: 6174052.3 | G10: 4.4887251e+09 | H10: 0 | I10: 0 | J10: 0 | K10: NA | L10: 0 | M10: 0 | AL10: =IF(H10<0,1,0) -> 0
A11: 10 | B11: BRA | C11: BAU | D11: 10 | E11: 2.2006505e+09 | F11: 7127383.4 | G11: 4.4901623e+09 | H11: 0 | I11: 0 | J11: 0 | K11: NA | L11: 0 | M11: 0 | AL11: =IF(H11<0,1,0) -> 0
A12: 11 | B12: BRA | C12: BAU | D12: 11 | E12: 1.5710401e+09 | F12: 6495027.9 | G12: 4.488279e+09 | H12: 0 | I12: 0 | J12: 0 | K12: NA | L12: 0 | M12: 0 | AL12: =IF(H12<0,1,0) -> 0
A13: 12 | B13: BRA | C13: BAU | D13: 12 | E13: 1.2650066e+09 | F13: 6793279.9 | G13: 4.4890955e+09 | H13: 0 | I13: 0 | J13: 0 | K13: NA | L13: 0 | M13: 0 | AL13: =IF(H13<0,1,0) -> 0
A14: 13 | B14: BRA | C14: BAU | D14: 13 | E14: 1.2944085e+09 | F14: 6746611.8 | G14: 4.4860779e+09 | H14: 0 | I14: 0 | J14: 0 | K14: NA | L14: 0 | M14: 0 | AL14: =IF(H14<0,1,0) -> 0
... A501: 500 | B501: BRA | C501: BAU | D501: 500 | E501: 1.921023e+09 | F501: 6760420.1 | G501: 4.4901251e+09 | H501: 0 | I501: 0 | J501: 0 | K501: NA | L501: 0 | M501: 0 | AL501: =IF(H501<0,1,0) -> 0
A502: 501 | B502: BRA | C502: DGN | D502: 1 | E502: 3.2168927e+09 | F502: 6479142 | G502: 4.4875984e+09 | H502: 1.3032182e+09 | I502: 239113.7 | J502: -1582149.2 | K502: 5450.203 | L502: 52072.473 | M502: 117711.54 | O502: =AVERAGE(E502:E1001) -> 2.1831962e+09 | P502: =_xlfn.PERCENTILE.INC(E502:E1001,0.5) -> 2.116189e+09 | Q502: =_xlfn.PERCENTILE.INC(E502:E1001,0.025) -> 1.4366555e+09 | R502: =_xlfn.PERCENTILE.INC(E502:E1001,0.975) -> 3.3808053e+09 | S502: =_xlfn.PERCENTILE.INC(H502:H1001,0.5) -> 5.4230203e+08 | T502: =AVERAGE(F502:F1001) -> 6349912.8 | U502: =_xlfn.PERCENTILE.INC(F502:F1001,0.5) -> 6379351.6 | V502: =_xlfn.PERCENTILE.INC(F502:F1001,0.025) -> 5597758.4 | W502: =_xlfn.PERCENTILE.INC(F502:F1001,0.975) -> 7077693.5 | Y502: =IF(K502<cet_BRA_lo,1,0) -> 1 | Z502: =IF(K502<cet_BRA_hi,1,0) -> 1 | AA502: =AVERAGE(Y502:Y1001) -> 0.808 | AB502: =AVERAGE(Z502:Z1001) -> 0.922 | AD502: =IF(L502<0,0,1) -> 1 | AE502: =IF(M502<0,0,1) -> 1 | AF502: =AVERAGE(AD502:AD1001) -> 0.808 | AG502: =AVERAGE(AE502:AE1001) -> 0.922 | AI502: =IF(Y502<>AD502,"ERROR!","") | AJ502: =IF(Z502<>AE502,"ERROR!","") | AL502: =IF(H502<0,1,0) -> 0 | AM502: =AVERAGE(AL502:AL1001) -> 0.08
A503: 502 | B503: BRA | C503: DGN | D503: 2 | E503: 2.0033601e+09 | F503: 6857083.6 | G503: 4.4880137e+09 | H503: 5.4830604e+08 | I503: 129921.59 | J503: -1104677.8 | K503: 4220.2842 | L503: 51227.299 | M503: 78843.776 | Y503: =IF(K503<cet_BRA_lo,1,0) -> 1 | Z503: =IF(K503<cet_BRA_hi,1,0) -> 1 | AD503: =IF(L503<0,0,1) -> 1 | AE503: =IF(M503<0,0,1) -> 1 | AI503: =IF(Y503<>AD503,"ERROR!","") | AJ503: =IF(Z503<>AE503,"ERROR!","") | AL503: =IF(H503<0,1,0) -> 0
A504: 503 | B504: BRA | C504: DGN | D504: 3 | E504: 1.9626738e+09 | F504: 6144949.6 | G504: 4.4863758e+09 | H504: 3.5884289e+08 | I504: 67652.411 | J504: -671072.06 | K504: 5304.2145 | L504: 16150.356 | M504: 34224.161 | Y504: =IF(K504<cet_BRA_lo,1,0) -> 1 | Z504: =IF(K504<cet_BRA_hi,1,0) -> 1 | AD504: =IF(L504<0,0,1) -> 1 | AE504: =IF(M504<0,0,1) -> 1 | AI504: =IF(Y504<>AD504,"ERROR!","") | AJ504: =IF(Z504<>AE504,"ERROR!","") | AL504: =IF(H504<0,1,0) -> 0
A505: 504 | B505: BRA | C505: DGN | D505: 4 | E505: 3.1258166e+09 | F505: 6157793.6 | G505: 4.4878795e+09 | H505: 1.4190098e+09 | I505: 257524.21 | J505: -1902921.8 | K505: 5510.1998 | L505: 53864.269 | M505: 125335.4 | Y505: =IF(K505<cet_BRA_lo,1,0) -> 1 | Z505: =IF(K505<cet_BRA_hi,1,0) -> 1 | AD505: =IF(L505<0,0,1) -> 1 | AE505: =IF(M505<0,0,1) -> 1 | AI505: =IF(Y505<>AD505,"ERROR!","") | AJ505: =IF(Z505<>AE505,"ERROR!","") | AL505: =IF(H505<0,1,0) -> 0
A506: 505 | B506: BRA | C506: DGN | D506: 5 | E506: 1.8869527e+09 | F506: 5970975.4 | G506: 4.4862021e+09 | H506: 5.1907469e+08 | I506: 62126.488 | J506: -682958.28 | K506: 8355.127 | L506: -12372.447 | M506: 13771.738 | Y506: =IF(K506<cet_BRA_lo,1,0) -> 0 | Z506: =IF(K506<cet_BRA_hi,1,0) -> 1 | AD506: =IF(L506<0,0,1) -> 0 | AE506: =IF(M506<0,0,1) -> 1 | AI506: =IF(Y506<>AD506,"ERROR!","") | AJ506: =IF(Z506<>AE506,"ERROR!","") | AL506: =IF(H506<0,1,0) -> 0
A507: 506 | B507: BRA | C507: DGN | D507: 6 | E507: 1.9919889e+09 | F507: 6161312.6 | G507: 4.4864034e+09 | H507: 7.697854e+08 | I507: 76507.991 | J507: -726110.19 | K507: 10061.503 | L507: -33973.59 | M507: 4798.1176 | Y507: =IF(K507<cet_BRA_lo,1,0) -> 0 | Z507: =IF(K507<cet_BRA_hi,1,0) -> 1 | AD507: =IF(L507<0,0,1) -> 0 | AE507: =IF(M507<0,0,1) -> 1 | AI507: =IF(Y507<>AD507,"ERROR!","") | AJ507: =IF(Z507<>AE507,"ERROR!","") | AL507: =IF(H507<0,1,0) -> 0
A508: 507 | B508: BRA | C508: DGN | D508: 7 | E508: 1.8966983e+09 | F508: 6211072.4 | G508: 4.4873069e+09 | H508: 4.7787477e+08 | I508: 70156.794 | J508: -715682.25 | K508: 6811.5252 | L508: 1570.978 | M508: 25640.051 | Y508: =IF(K508<cet_BRA_lo,1,0) -> 1 | Z508: =IF(K508<cet_BRA_hi,1,0) -> 1 | AD508: =IF(L508<0,0,1) -> 1 | AE508: =IF(M508<0,0,1) -> 1 | AI508: =IF(Y508<>AD508,"ERROR!","") | AJ508: =IF(Z508<>AE508,"ERROR!","") | AL508: =IF(H508<0,1,0) -> 0
A509: 508 | B509: BRA | C509: DGN | D509: 8 | E509: 2.7530671e+09 | F509: 6564200.2 | G509: 4.4897072e+09 | H509: 1.1061115e+09 | I509: 144584.67 | J509: -1326834.1 | K509: 7650.2676 | L509: -14167.285 | M509: 41544.124 | Y509: =IF(K509<cet_BRA_lo,1,0) -> 0 | Z509: =IF(K509<cet_BRA_hi,1,0) -> 1 | AD509: =IF(L509<0,0,1) -> 0 | AE509: =IF(M509<0,0,1) -> 1 | AI509: =IF(Y509<>AD509,"ERROR!","") | AJ509: =IF(Z509<>AE509,"ERROR!","") | AL509: =IF(H509<0,1,0) -> 0
A510: 509 | B510: BRA | C510: DGN | D510: 9 | E510: 2.592178e+09 | F510: 6066653 | G510: 4.4877377e+09 | H510: -8479399.5 | I510: 107399.38 | J510: -987390.16 | K510: -78.952036 | L510: 108616.36 | M510: 108189.28 | Y510: =IF(K510<cet_BRA_lo,1,0) -> 1 | Z510: =IF(K510<cet_BRA_hi,1,0) -> 1 | AD510: =IF(L510<0,0,1) -> 1 | AE510: =IF(M510<0,0,1) -> 1 | AI510: =IF(Y510<>AD510,"ERROR!","") | AJ510: =IF(Z510<>AE510,"ERROR!","") | AL510: =IF(H510<0,1,0) -> 1
A511: 510 | B511: BRA | C511: DGN | D511: 10 | E511: 2.6178834e+09 | F511: 6902196.6 | G511: 4.4885143e+09 | H511: 4.1723293e+08 | I511: 225186.83 | J511: -1647943.9 | K511: 1852.83 | L511: 165304.49 | M511: 186319.22 | Y511: =IF(K511<cet_BRA_lo,1,0) -> 1 | Z511: =IF(K511<cet_BRA_hi,1,0) -> 1 | AD511: =IF(L511<0,0,1) -> 1 | AE511: =IF(M511<0,0,1) -> 1 | AI511: =IF(Y511<>AD511,"ERROR!","") | AJ511: =IF(Z511<>AE511,"ERROR!","") | AL511: =IF(H511<0,1,0) -> 0
A512: 511 | B512: BRA | C512: DGN | D512: 11 | E512: 2.3900741e+09 | F512: 6282423.1 | G512: 4.4868224e+09 | H512: 8.1903399e+08 | I512: 212604.79 | J512: -1456574 | K512: 3852.3779 | L512: 95054.926 | M512: 136307.13 | Y512: =IF(K512<cet_BRA_lo,1,0) -> 1 | Z512: =IF(K512<cet_BRA_hi,1,0) -> 1 | AD512: =IF(L512<0,0,1) -> 1 | AE512: =IF(M512<0,0,1) -> 1 | AI512: =IF(Y512<>AD512,"ERROR!","") | AJ512: =IF(Z512<>AE512,"ERROR!","") | AL512: =IF(H512<0,1,0) -> 0
A513: 512 | B513: BRA | C513: DGN | D513: 12 | E513: 1.7041052e+09 | F513: 6693886.3 | G513: 4.4882082e+09 | H513: 4.3909864e+08 | I513: 99393.513 | J513: -887279.55 | K513: 4417.7797 | L513: 36372.947 | M513: 58488.986 | Y513: =IF(K513<cet_BRA_lo,1,0) -> 1 | Z513: =IF(K513<cet_BRA_hi,1,0) -> 1 | AD513: =IF(L513<0,0,1) -> 1 | AE513: =IF(M513<0,0,1) -> 1 | AI513: =IF(Y513<>AD513,"ERROR!","") | AJ513: =IF(Z513<>AE513,"ERROR!","") | AL513: =IF(H513<0,1,0) -> 0
A514: 513 | B514: BRA | C514: DGN | D514: 13 | E514: 2.5737604e+09 | F514: 6562216.5 | G514: 4.4849371e+09 | H514: 1.2793519e+09 | I514: 184395.31 | J514: -1140796.5 | K514: 6938.0936 | L514: 779.43158 | M514: 65216.426 | Y514: =IF(K514<cet_BRA_lo,1,0) -> 1 | Z514: =IF(K514<cet_BRA_hi,1,0) -> 1 | AD514: =IF(L514<0,0,1) -> 1 | AE514: =IF(M514<0,0,1) -> 1 | AI514: =IF(Y514<>AD514,"ERROR!","") | AJ514: =IF(Z514<>AE514,"ERROR!","") | AL514: =IF(H514<0,1,0) -> 0
... A1001: 1000 | B1001: BRA | C1001: DGN | D1001: 500 | E1001: 2.9976785e+09 | F1001: 6497939.6 | G1001: 4.4882903e+09 | H1001: 1.0766556e+09 | I1001: 262480.53 | J1001: -1834787.3 | K1001: 4101.8493 | L1001: 107956.16 | M1001: 162183.96 | Y1001: =IF(K1001<cet_BRA_lo,1,0) -> 1 | Z1001: =IF(K1001<cet_BRA_hi,1,0) -> 1 | AD1001: =IF(L1001<0,0,1) -> 1 | AE1001: =IF(M1001<0,0,1) -> 1 | AI1001: =IF(Y1001<>AD1001,"ERROR!","") | AJ1001: =IF(Z1001<>AE1001,"ERROR!","") | AL1001: =IF(H1001<0,1,0) -> 0
A1002: 1001 | B1002: BRA | C1002: DST | D1002: 1 | E1002: 2.3544406e+09 | F1002: 6486396.6 | G1002: 4.4883241e+09 | H1002: 4.4076616e+08 | I1002: 231859.12 | J1002: -856501.86 | K1002: 1901.0085 | L1002: 168599.23 | M1002: 190799.25 | O1002: =AVERAGE(E1002:E1501) -> 1.8578186e+09 | P1002: =_xlfn.PERCENTILE.INC(E1002:E1501,0.5) -> 1.7702482e+09 | Q1002: =_xlfn.PERCENTILE.INC(E1002:E1501,0.025) -> 1.0986613e+09 | R1002: =_xlfn.PERCENTILE.INC(E1002:E1501,0.975) -> 2.9298221e+09 | S1002: =_xlfn.PERCENTILE.INC(H1002:H1501,0.5) -> 1.8259602e+08 | T1002: =AVERAGE(F1002:F1501) -> 6377085.2 | U1002: =_xlfn.PERCENTILE.INC(F1002:F1501,0.5) -> 6411393.4 | V1002: =_xlfn.PERCENTILE.INC(F1002:F1501,0.025) -> 5599976.4 | W1002: =_xlfn.PERCENTILE.INC(F1002:F1501,0.975) -> 7111395.5 | Y1002: =IF(K1002<cet_BRA_lo,1,0) -> 1 | Z1002: =IF(K1002<cet_BRA_hi,1,0) -> 1 | AA1002: =AVERAGE(Y1002:Y1501) -> 1 | AB1002: =AVERAGE(Z1002:Z1501) -> 1 | AD1002: =IF(L1002<0,0,1) -> 1 | AE1002: =IF(M1002<0,0,1) -> 1 | AF1002: =AVERAGE(AD1002:AD1501) -> 1 | AG1002: =AVERAGE(AE1002:AE1501) -> 1 | AI1002: =IF(Y1002<>AD1002,"ERROR!","") | AJ1002: =IF(Z1002<>AE1002,"ERROR!","") | AL1002: =IF(H1002<0,1,0) -> 0 | AM1002: =AVERAGE(AL1002:AL1501) -> 0
A1003: 1002 | B1003: BRA | C1003: DST | D1003: 2 | E1003: 1.6550354e+09 | F1003: 6879078.5 | G1003: 4.4886872e+09 | H1003: 1.9998131e+08 | I1003: 107926.78 | J1003: -431227.36 | K1003: 1852.935 | L1003: 79224.949 | M1003: 89297.389 | Y1003: =IF(K1003<cet_BRA_lo,1,0) -> 1 | Z1003: =IF(K1003<cet_BRA_hi,1,0) -> 1 | AD1003: =IF(L1003<0,0,1) -> 1 | AE1003: =IF(M1003<0,0,1) -> 1 | AI1003: =IF(Y1003<>AD1003,"ERROR!","") | AJ1003: =IF(Z1003<>AE1003,"ERROR!","") | AL1003: =IF(H1003<0,1,0) -> 0
A1004: 1003 | B1004: BRA | C1004: DST | D1004: 3 | E1004: 1.7027529e+09 | F1004: 6187964.6 | G1004: 4.4869618e+09 | H1004: 98921991 | I1004: 24637.377 | J1004: -84987.937 | K1004: 4015.1187 | L1004: 10439.838 | M1004: 15422.233 | Y1004: =IF(K1004<cet_BRA_lo,1,0) -> 1 | Z1004: =IF(K1004<cet_BRA_hi,1,0) -> 1 | AD1004: =IF(L1004<0,0,1) -> 1 | AE1004: =IF(M1004<0,0,1) -> 1 | AI1004: =IF(Y1004<>AD1004,"ERROR!","") | AJ1004: =IF(Z1004<>AE1004,"ERROR!","") | AL1004: =IF(H1004<0,1,0) -> 0
A1005: 1004 | B1005: BRA | C1005: DST | D1005: 4 | E1005: 2.3413188e+09 | F1005: 6152552.6 | G1005: 4.4886881e+09 | H1005: 6.3451202e+08 | I1005: 262765.14 | J1005: -1094261.5 | K1005: 2414.7496 | L1005: 171698.35 | M1005: 203656.75 | Y1005: =IF(K1005<cet_BRA_lo,1,0) -> 1 | Z1005: =IF(K1005<cet_BRA_hi,1,0) -> 1 | AD1005: =IF(L1005<0,0,1) -> 1 | AE1005: =IF(M1005<0,0,1) -> 1 | AI1005: =IF(Y1005<>AD1005,"ERROR!","") | AJ1005: =IF(Z1005<>AE1005,"ERROR!","") | AL1005: =IF(H1005<0,1,0) -> 0
A1006: 1005 | B1006: BRA | C1006: DST | D1006: 5 | E1006: 1.4357161e+09 | F1006: 6014213.8 | G1006: 4.4868144e+09 | H1006: 67838077 | I1006: 18888.107 | J1006: -70627.858 | K1006: 3591.5763 | L1006: 9151.8119 | M1006: 12568.606 | Y1006: =IF(K1006<cet_BRA_lo,1,0) -> 1 | Z1006: =IF(K1006<cet_BRA_hi,1,0) -> 1 | AD1006: =IF(L1006<0,0,1) -> 1 | AE1006: =IF(M1006<0,0,1) -> 1 | AI1006: =IF(Y1006<>AD1006,"ERROR!","") | AJ1006: =IF(Z1006<>AE1006,"ERROR!","") | AL1006: =IF(H1006<0,1,0) -> 0
A1007: 1006 | B1007: BRA | C1007: DST | D1007: 6 | E1007: 1.304519e+09 | F1007: 6198141.8 | G1007: 4.4869896e+09 | H1007: 82315548 | I1007: 39678.797 | J1007: -139973.52 | K1007: 2074.5475 | L1007: 27864.658 | M1007: 32010.637 | Y1007: =IF(K1007<cet_BRA_lo,1,0) -> 1 | Z1007: =IF(K1007<cet_BRA_hi,1,0) -> 1 | AD1007: =IF(L1007<0,0,1) -> 1 | AE1007: =IF(M1007<0,0,1) -> 1 | AI1007: =IF(Y1007<>AD1007,"ERROR!","") | AJ1007: =IF(Z1007<>AE1007,"ERROR!","") | AL1007: =IF(H1007<0,1,0) -> 0
A1008: 1007 | B1008: BRA | C1008: DST | D1008: 7 | E1008: 1.5435826e+09 | F1008: 6248092.8 | G1008: 4.4879059e+09 | H1008: 1.2475907e+08 | I1008: 33136.357 | J1008: -116738.33 | K1008: 3765.0209 | L1008: 15230.614 | M1008: 21514.342 | Y1008: =IF(K1008<cet_BRA_lo,1,0) -> 1 | Z1008: =IF(K1008<cet_BRA_hi,1,0) -> 1 | AD1008: =IF(L1008<0,0,1) -> 1 | AE1008: =IF(M1008<0,0,1) -> 1 | AI1008: =IF(Y1008<>AD1008,"ERROR!","") | AJ1008: =IF(Z1008<>AE1008,"ERROR!","") | AL1008: =IF(H1008<0,1,0) -> 0
A1009: 1008 | B1009: BRA | C1009: DST | D1009: 8 | E1009: 2.0017805e+09 | F1009: 6573837.5 | G1009: 4.4904797e+09 | H1009: 3.5482493e+08 | I1009: 134947.33 | J1009: -554268.88 | K1009: 2629.3587 | L1009: 84021.942 | M1009: 101893.38 | Y1009: =IF(K1009<cet_BRA_lo,1,0) -> 1 | Z1009: =IF(K1009<cet_BRA_hi,1,0) -> 1 | AD1009: =IF(L1009<0,0,1) -> 1 | AE1009: =IF(M1009<0,0,1) -> 1 | AI1009: =IF(Y1009<>AD1009,"ERROR!","") | AJ1009: =IF(Z1009<>AE1009,"ERROR!","") | AL1009: =IF(H1009<0,1,0) -> 0
A1010: 1009 | B1010: BRA | C1010: DST | D1010: 9 | E1010: 2.7944128e+09 | F1010: 6093649.3 | G1010: 4.4884095e+09 | H1010: 1.9375543e+08 | I1010: 80403.051 | J1010: -315577.35 | K1010: 2409.802 | L1010: 52594.773 | M1010: 62353.635 | Y1010: =IF(K1010<cet_BRA_lo,1,0) -> 1 | Z1010: =IF(K1010<cet_BRA_hi,1,0) -> 1 | AD1010: =IF(L1010<0,0,1) -> 1 | AE1010: =IF(M1010<0,0,1) -> 1 | AI1010: =IF(Y1010<>AD1010,"ERROR!","") | AJ1010: =IF(Z1010<>AE1010,"ERROR!","") | AL1010: =IF(H1010<0,1,0) -> 0
A1011: 1010 | B1011: BRA | C1011: DST | D1011: 10 | E1011: 2.6850857e+09 | F1011: 6902749.7 | G1011: 4.4892503e+09 | H1011: 4.8443522e+08 | I1011: 224633.75 | J1011: -911928.74 | K1011: 2156.5558 | L1011: 155106.37 | M1011: 179505.87 | Y1011: =IF(K1011<cet_BRA_lo,1,0) -> 1 | Z1011: =IF(K1011<cet_BRA_hi,1,0) -> 1 | AD1011: =IF(L1011<0,0,1) -> 1 | AE1011: =IF(M1011<0,0,1) -> 1 | AI1011: =IF(Y1011<>AD1011,"ERROR!","") | AJ1011: =IF(Z1011<>AE1011,"ERROR!","") | AL1011: =IF(H1011<0,1,0) -> 0
A1012: 1011 | B1012: BRA | C1012: DST | D1012: 11 | E1012: 1.9449086e+09 | F1012: 6300588.1 | G1012: 4.4875317e+09 | H1012: 3.7386853e+08 | I1012: 194439.76 | J1012: -747286.06 | K1012: 1922.7988 | L1012: 140781.19 | M1012: 159611.79 | Y1012: =IF(K1012<cet_BRA_lo,1,0) -> 1 | Z1012: =IF(K1012<cet_BRA_hi,1,0) -> 1 | AD1012: =IF(L1012<0,0,1) -> 1 | AE1012: =IF(M1012<0,0,1) -> 1 | AI1012: =IF(Y1012<>AD1012,"ERROR!","") | AJ1012: =IF(Z1012<>AE1012,"ERROR!","") | AL1012: =IF(H1012<0,1,0) -> 0
...

Sheet Currencies & CETs
A1: CURRENCIES | B1: Conversion ratea (World Bank: DEC alternative conversion factor, 2023) | H1: Cost-effectiveness thresholds
B2: https://wdi.worldbank.org/table/4.16# | H2: Ochalek
E3: Mean cost (US$) | F3: Mean cost (R$) | H3: Lower bound | I3: Upper bound
A4: BRAZIL | B4: 4.99 | C4: BRA | D4: BAU | E4: =Summaries!D2 -> 1.6111629e+09 | F4: =E4*BRA -> 8.0397031e+09 | H4: 6967.55 | I4: 10734.72
C5: BRA | D5: VAX | E5: =Summaries!D3 -> 3.9637137e+09 | F5: =E5*BRA -> 1.9778932e+10
C6: BRA | D6: TPT | E6: =Summaries!D4 -> 1.6615746e+09 | F6: =E6*BRA -> 8.291257e+09
C7: BRA | D7: SCRhi | E7: =Summaries!D5 -> 3.853532e+10 | F7: =E7*BRA -> 1.9229125e+11
C8: BRA | D8: SCRlo | E8: =Summaries!D6 -> 8.1011788e+09 | F8: =E8*BRA -> 4.0424882e+10
C9: BRA | D9: DGN | E9: =Summaries!D7 -> 2.1831962e+09 | F9: =E9*BRA -> 1.0894149e+10
C10: BRA | D10: DST | E10: =Summaries!D8 -> 1.8578186e+09 | F10: =E10*BRA -> 9.2705148e+09
C11: BRA | D11: SDS | E11: =Summaries!D9 -> 1.7092527e+09 | F11: =E11*BRA -> 8.5291709e+09
C12: BRA | D12: SDR | E12: =Summaries!D10 -> 1.274696e+09 | F12: =E12*BRA -> 6.3607333e+09
C13: BRA | D13: PRI | E13: =Summaries!D11 -> 1.8018965e+09 | F13: =E13*BRA -> 8.9914634e+09
F14: Mean cost (INR)
A15: INDIA | B15: 82.79 | C15: IND | D15: BAU | E15: =Summaries!D13 -> 1.791574e+10 | F15: =E15*IND -> 1.4832441e+12 | H15: 413.47 | I15: 568.52
C16: IND | D16: VAX | E16: =Summaries!D14 -> 3.3480308e+10 | F16: =E16*IND -> 2.7718347e+12
C17: IND | D17: TPT | E17: =Summaries!D15 -> 1.9144619e+10 | F17: =E17*IND -> 1.584983e+12
C18: IND | D18: SCRhi | E18: =Summaries!D16 -> 2.6199254e+11 | F18: =E18*IND -> 2.1690362e+13
C19: IND | D19: SCRlo | E19: =Summaries!D17 -> 4.9093181e+10 | F19: =E19*IND -> 4.0644245e+12
C20: IND | D20: DGN | E20: =Summaries!D18 -> 2.9433166e+10 | F20: =E20*IND -> 2.4367718e+12
C21: IND | D21: DST | E21: =Summaries!D19 -> 1.8680484e+10 | F21: =E21*IND -> 1.5465573e+12
C22: IND | D22: SDS | E22: =Summaries!D20 -> 1.9360839e+10 | F22: =E22*IND -> 1.6028838e+12
C23: IND | D23: SDR | E23: =Summaries!D21 -> 1.7607656e+10 | F23: =E23*IND -> 1.4577378e+12
C24: IND | D24: NTN | E24: =Summaries!D22 -> 2.0172411e+10 | F24: =E24*IND -> 1.6700739e+12
F25: Mean cost (R)
A26: SOUTH AFRICA | B26: 18.45 | C26: ZAF | D26: BAU | E26: =Summaries!D24 -> 2.5592577e+09 | F26: =E26*ZAF -> 4.7218304e+10 | H26: 2443.59 | I26: 3285.06
C27: ZAF | D27: VAX | E27: =Summaries!D25 -> 3.1384222e+09 | F27: =E27*ZAF -> 5.790389e+10
C28: ZAF | D28: TPT | E28: =Summaries!D26 -> 2.7196612e+09 | F28: =E28*ZAF -> 5.0177749e+10
C29: ZAF | D29: SCRhi | E29: =Summaries!D27 -> 1.2310247e+10 | F29: =E29*ZAF -> 2.2712405e+11
C30: ZAF | D30: SCRlo | E30: =Summaries!D28 -> 4.4879331e+09 | F30: =E30*ZAF -> 8.2802365e+10
C31: ZAF | D31: DGN | E31: =Summaries!D29 -> 2.7351811e+09 | F31: =E31*ZAF -> 5.0464091e+10
C32: ZAF | D32: DST | E32: =Summaries!D30 -> 2.5809917e+09 | F32: =E32*ZAF -> 4.7619297e+10
C33: ZAF | D33: SDS | E33: =Summaries!D31 -> 2.6457582e+09 | F33: =E33*ZAF -> 4.8814238e+10
C34: ZAF | D34: SDR | E34: =Summaries!D32 -> 2.5221535e+09 | F34: =E34*ZAF -> 4.6533732e+10

Sheet Summaries
C1: Mean cost (R$) | D1: Mean cost (US$) | E1: Incr mean cost | F1: Mean DALYs | G1: Incr DALYs | H1: ICERs vs BAU | I1: % CE at Och low CET | J1: % CE at Och high CET | L1: Median cost | M1: 2.5% cost | N1: 97.5% cost | O1: Incr median cost | P1: Median incr cost | R1: Median DALYs | S1: 2.5% DALYs | T1: 97.5% DALYs | U1: Incr median DALYs averted | V1: Median incr DALYs averted
A2: BRA | B2: BAU | C2: ='Currencies & CETs'!F4 -> 8.0397031e+09 | D2: ='ceasumm_raw_results (260519)'!O2 -> 1.6111629e+09 | F2: ='ceasumm_raw_results (260519)'!T2 -> 6489723.6 | L2: ='ceasumm_raw_results (260519)'!P2 -> 1.5685268e+09 | M2: ='ceasumm_raw_results (260519)'!Q2 -> 9.9586562e+08 | N2: ='ceasumm_raw_results (260519)'!R2 -> 2.3960757e+09 | R2: ='ceasumm_raw_results (260519)'!U2 -> 6494616.6 | S2: ='ceasumm_raw_results (260519)'!V2 -> 5742336.3 | T2: ='ceasumm_raw_results (260519)'!W2 -> 7190390.5
A3: BRA | B3: VAX | C3: ='Currencies & CETs'!F5 -> 1.9778932e+10 | D3: ='ceasumm_raw_results (260519)'!O4502 -> 3.9637137e+09 | E3: =D3-D$2 -> 2.3525508e+09 | F3: ='ceasumm_raw_results (260519)'!T4502 -> 5002774.8 | G3: =F$2-F3 -> 1486948.7 | H3: =E3/G3 -> 1582.1331 | I3: ='ceasumm_raw_results (260519)'!AA4502 -> 1 | J3: ='ceasumm_raw_results (260519)'!AB4502 -> 1 | L3: ='ceasumm_raw_results (260519)'!P4502 -> 3.9455913e+09 | M3: ='ceasumm_raw_results (260519)'!Q4502 -> 2.6037694e+09 | N3: ='ceasumm_raw_results (260519)'!R4502 -> 5.4951414e+09 | O3: =N3-N$2 -> 3.0990657e+09 | P3: ='ceasumm_raw_results (260519)'!S4502 -> 2.301548e+09 | R3: ='ceasumm_raw_results (260519)'!U4502 -> 5009831 | S3: ='ceasumm_raw_results (260519)'!V4502 -> 4378366.9 | T3: ='ceasumm_raw_results (260519)'!W4502 -> 5588273 | U3: =T$2-T3 -> 1602117.6
A4: BRA | B4: TPT | C4: ='Currencies & CETs'!F6 -> 8.291257e+09 | D4: ='ceasumm_raw_results (260519)'!O4002 -> 1.6615746e+09 | E4: =D4-D$2 -> 50411611 | F4: ='ceasumm_raw_results (260519)'!T4002 -> 6426637.3 | G4: =F$2-F4 -> 63086.293 | H4: =E4/G4 -> 799.08977 | I4: ='ceasumm_raw_results (260519)'!AA4002 -> 1 | J4: ='ceasumm_raw_results (260519)'!AB4002 -> 1 | L4: ='ceasumm_raw_results (260519)'!P4002 -> 1.6156168e+09 | M4: ='ceasumm_raw_results (260519)'!Q4002 -> 1.0444483e+09 | N4: ='ceasumm_raw_results (260519)'!R4002 -> 2.446833e+09 | O4: =N4-N$2 -> 50757229 | P4: ='ceasumm_raw_results (260519)'!S4002 -> 49792879 | R4: ='ceasumm_raw_results (260519)'!U4002 -> 6432202.5 | S4: ='ceasumm_raw_results (260519)'!V4002 -> 5686933.2 | T4: ='ceasumm_raw_results (260519)'!W4002 -> 7112344.8 | U4: =T$2-T4 -> 78045.733
A5: BRA | B5: SCRhi | C5: ='Currencies & CETs'!F7 -> 1.9229125e+11 | D5: ='ceasumm_raw_results (260519)'!O2002 -> 3.853532e+10 | E5: =D5-D$2 -> 3.6924157e+10 | F5: ='ceasumm_raw_results (260519)'!T2002 -> 3903161.6 | G5: =F$2-F5 -> 2586561.9 | H5: =E5/G5 -> 14275.381 | I5: ='ceasumm_raw_results (260519)'!AA2002 -> 0.008 | J5: ='ceasumm_raw_results (260519)'!AB2002 -> 0.182 | L5: ='ceasumm_raw_results (260519)'!P2002 -> 3.7573876e+10 | M5: ='ceasumm_raw_results (260519)'!Q2002 -> 2.2623541e+10 | N5: ='ceasumm_raw_results (260519)'!R2002 -> 6.035868e+10 | O5: =N5-N$2 -> 5.7962605e+10 | P5: ='ceasumm_raw_results (260519)'!S2002 -> 3.5830813e+10 | R5: ='ceasumm_raw_results (260519)'!U2002 -> 3929987.5 | S5: ='ceasumm_raw_results (260519)'!V2002 -> 3337533.6 | T5: ='ceasumm_raw_results (260519)'!W2002 -> 4383219.7 | U5: =T$2-T5 -> 2807170.8
A6: BRA | B6: SCRlo | C6: ='Currencies & CETs'!F8 -> 4.0424882e+10 | D6: ='ceasumm_raw_results (260519)'!O2502 -> 8.1011788e+09 | E6: =D6-D$2 -> 6.4900159e+09 | F6: ='ceasumm_raw_results (260519)'!T2502 -> 3903161.6 | G6: =F$2-F6 -> 2586561.9 | H6: =E6/G6 -> 2509.1283 | I6: ='ceasumm_raw_results (260519)'!AA2502 -> 1 | J6: ='ceasumm_raw_results (260519)'!AB2502 -> 1 | L6: ='ceasumm_raw_results (260519)'!P2502 -> 7.9772279e+09 | M6: ='ceasumm_raw_results (260519)'!Q2502 -> 5.7470611e+09 | N6: ='ceasumm_raw_results (260519)'!R2502 -> 1.0810482e+10 | O6: =N6-N$2 -> 8.4144058e+09 | P6: ='ceasumm_raw_results (260519)'!S2502 -> 6.3998838e+09 | R6: ='ceasumm_raw_results (260519)'!U2502 -> 3929987.5 | S6: ='ceasumm_raw_results (260519)'!V2502 -> 3337533.6 | T6: ='ceasumm_raw_results (260519)'!W2502 -> 4383219.7 | U6: =T$2-T6 -> 2807170.8
A7: BRA | B7: DGN | C7: ='Currencies & CETs'!F9 -> 1.0894149e+10 | D7: ='ceasumm_raw_results (260519)'!O502 -> 2.1831962e+09 | E7: =D7-D$2 -> 5.7203329e+08 | F7: ='ceasumm_raw_results (260519)'!T502 -> 6349912.8 | G7: =F$2-F7 -> 139810.72 | H7: =E7/G7 -> 4091.4838 | I7: ='ceasumm_raw_results (260519)'!AA502 -> 0.808 | J7: ='ceasumm_raw_results (260519)'!AB502 -> 0.922 | L7: ='ceasumm_raw_results (260519)'!P502 -> 2.116189e+09 | M7: ='ceasumm_raw_results (260519)'!Q502 -> 1.4366555e+09 | N7: ='ceasumm_raw_results (260519)'!R502 -> 3.3808053e+09 | O7: =N7-N$2 -> 9.8472961e+08 | P7: ='ceasumm_raw_results (260519)'!S502 -> 5.4230203e+08 | R7: ='ceasumm_raw_results (260519)'!U502 -> 6379351.6 | S7: ='ceasumm_raw_results (260519)'!V502 -> 5597758.4 | T7: ='ceasumm_raw_results (260519)'!W502 -> 7077693.5 | U7: =T$2-T7 -> 112697.07
A8: BRA | B8: DST | C8: ='Currencies & CETs'!F10 -> 9.2705148e+09 | D8: ='ceasumm_raw_results (260519)'!O1002 -> 1.8578186e+09 | E8: =D8-D$2 -> 2.4665566e+08 | F8: ='ceasumm_raw_results (260519)'!T1002 -> 6377085.2 | G8: =F$2-F8 -> 112638.4 | H8: =E8/G8 -> 2189.8008 | I8: ='ceasumm_raw_results (260519)'!AA1002 -> 1 | J8: ='ceasumm_raw_results (260519)'!AB1002 -> 1 | L8: ='ceasumm_raw_results (260519)'!P1002 -> 1.7702482e+09 | M8: ='ceasumm_raw_results (260519)'!Q1002 -> 1.0986613e+09 | N8: ='ceasumm_raw_results (260519)'!R1002 -> 2.9298221e+09 | O8: =N8-N$2 -> 5.337464e+08 | P8: ='ceasumm_raw_results (260519)'!S1002 -> 1.8259602e+08 | R8: ='ceasumm_raw_results (260519)'!U1002 -> 6411393.4 | S8: ='ceasumm_raw_results (260519)'!V1002 -> 5599976.4 | T8: ='ceasumm_raw_results (260519)'!W1002 -> 7111395.5 | U8: =T$2-T8 -> 78994.995
A9: BRA | B9: SDS | C9: ='Currencies & CETs'!F11 -> 8.5291709e+09 | D9: ='ceasumm_raw_results (260519)'!O3502 -> 1.7092527e+09 | E9: =D9-D$2 -> 98089750 | F9: ='ceasumm_raw_results (260519)'!T3502 -> 6489723.6 | G9: =F$2-F9 -> 0 | H9: =E9/G9 -> #DIV/0! | I9: ='ceasumm_raw_results (260519)'!AA3502 -> 0 | J9: ='ceasumm_raw_results (260519)'!AB3502 -> 0 | L9: ='ceasumm_raw_results (260519)'!P3502 -> 1.6654778e+09 | M9: ='ceasumm_raw_results (260519)'!Q3502 -> 1.1121596e+09 | N9: ='ceasumm_raw_results (260519)'!R3502 -> 2.4913548e+09 | O9: =N9-N$2 -> 95279061 | P9: ='ceasumm_raw_results (260519)'!S3502 -> 96640387 | R9: ='ceasumm_raw_results (260519)'!U3502 -> 6494616.6 | S9: ='ceasumm_raw_results (260519)'!V3502 -> 5742336.3 | T9: ='ceasumm_raw_results (260519)'!W3502 -> 7190390.5 | U9: =T$2-T9 -> 0
A10: BRA | B10: SDR | C10: ='Currencies & CETs'!F12 -> 6.3607333e+09 | D10: ='ceasumm_raw_results (260519)'!O3002 -> 1.274696e+09 | E10: =D10-D$2 -> -3.364669e+08 | F10: ='ceasumm_raw_results (260519)'!T3002 -> 6379224.9 | G10: =F$2-F10 -> 110498.64 | H10: =E10/G10 -> -3044.9869 | I10: ='ceasumm_raw_results (260519)'!AA3002 -> 1 | J10: ='ceasumm_raw_results (260519)'!AB3002 -> 1 | L10: ='ceasumm_raw_results (260519)'!P3002 -> 1.2727824e+09 | M10: ='ceasumm_raw_results (260519)'!Q3002 -> 7.7671201e+08 | N10: ='ceasumm_raw_results (260519)'!R3002 -> 1.9400142e+09 | O10: =N10-N$2 -> -4.560615e+08 | P10: ='ceasumm_raw_results (260519)'!S3002 -> -2.4670564e+08 | R10: ='ceasumm_raw_results (260519)'!U3002 -> 6408186.2 | S10: ='ceasumm_raw_results (260519)'!V3002 -> 5616669.7 | T10: ='ceasumm_raw_results (260519)'!W3002 -> 7105605.3 | U10: =T$2-T10 -> 84785.192
A11: BRA | B11: PRI | C11: ='Currencies & CETs'!F13 -> 8.9914634e+09 | D11: ='ceasumm_raw_results (260519)'!O1502 -> 1.8018965e+09 | E11: =D11-D$2 -> 1.9073354e+08 | F11: ='ceasumm_raw_results (260519)'!T1502 -> 5185462.6 | G11: =F$2-F11 -> 1304261 | H11: =E11/G11 -> 146.23878 | I11: ='ceasumm_raw_results (260519)'!AA1502 -> 1 | J11: ='ceasumm_raw_results (260519)'!AB1502 -> 1 | L11: ='ceasumm_raw_results (260519)'!P1502 -> 1.7529438e+09 | M11: ='ceasumm_raw_results (260519)'!Q1502 -> 1.1514729e+09 | N11: ='ceasumm_raw_results (260519)'!R1502 -> 2.6435714e+09 | O11: =N11-N$2 -> 2.4749566e+08 | P11: ='ceasumm_raw_results (260519)'!S1502 -> 1.8426827e+08 | R11: ='ceasumm_raw_results (260519)'!U1502 -> 5191452.7 | S11: ='ceasumm_raw_results (260519)'!V1502 -> 4627462.9 | T11: ='ceasumm_raw_results (260519)'!W1502 -> 5778311.2 | U11: =T$2-T11 -> 1412079.3
C12: Mean cost (INR) | O12: =O6/O5 -> 0.14516956 | P12: =P6/P5 -> 0.17861397
A13: IND | B13: BAU | C13: ='Currencies & CETs'!F15 -> 1.4832441e+12 | D13: ='ceasumm_raw_results (260519)'!O5002 -> 1.791574e+10 | F13: ='ceasumm_raw_results (260519)'!T5002 -> 91200660 | L13: ='ceasumm_raw_results (260519)'!P5002 -> 1.7510506e+10 | M13: ='ceasumm_raw_results (260519)'!Q5002 -> 1.2335695e+10 | N13: ='ceasumm_raw_results (260519)'!R5002 -> 2.5638868e+10 | P13: ='ceasumm_raw_results (260519)'!S5002 -> 0 | R13: ='ceasumm_raw_results (260519)'!U5002 -> 91456960 | S13: ='ceasumm_raw_results (260519)'!V5002 -> 88194081 | T13: ='ceasumm_raw_results (260519)'!W5002 -> 93353404
A14: IND | B14: VAX | C14: ='Currencies & CETs'!F16 -> 2.7718347e+12 | D14: ='ceasumm_raw_results (260519)'!O9502 -> 3.3480308e+10 | E14: =D14-D$13 -> 1.5564568e+10 | F14: ='ceasumm_raw_results (260519)'!T9502 -> 80713121 | G14: =F$13-F14 -> 10487539 | H14: =E14/G14 -> 1484.1011 | I14: ='ceasumm_raw_results (260519)'!AA9502 -> 0 | J14: ='ceasumm_raw_results (260519)'!AB9502 -> 0.002 | L14: ='ceasumm_raw_results (260519)'!P9502 -> 3.3070365e+10 | M14: ='ceasumm_raw_results (260519)'!Q9502 -> 2.3498578e+10 | N14: ='ceasumm_raw_results (260519)'!R9502 -> 4.4045202e+10 | O14: =N14-N$13 -> 1.8406334e+10 | P14: ='ceasumm_raw_results (260519)'!S9502 -> 1.5437434e+10 | R14: ='ceasumm_raw_results (260519)'!U9502 -> 80989596 | S14: ='ceasumm_raw_results (260519)'!V9502 -> 77529295 | T14: ='ceasumm_raw_results (260519)'!W9502 -> 83016818 | U14: =T$13-T14 -> 10336587
A15: IND | B15: TPT | C15: ='Currencies & CETs'!F17 -> 1.584983e+12 | D15: ='ceasumm_raw_results (260519)'!O9002 -> 1.9144619e+10 | E15: =D15-D$13 -> 1.2288796e+09 | F15: ='ceasumm_raw_results (260519)'!T9002 -> 88084845 | G15: =F$13-F15 -> 3115814.9 | H15: =E15/G15 -> 394.40071 | I15: ='ceasumm_raw_results (260519)'!AA9002 -> 0.628 | J15: ='ceasumm_raw_results (260519)'!AB9002 -> 0.976 | L15: ='ceasumm_raw_results (260519)'!P9002 -> 1.8719353e+10 | M15: ='ceasumm_raw_results (260519)'!Q9002 -> 1.3511458e+10 | N15: ='ceasumm_raw_results (260519)'!R9002 -> 2.6966965e+10 | O15: =N15-N$13 -> 1.3280971e+09 | P15: ='ceasumm_raw_results (260519)'!S9002 -> 1.2049721e+09 | R15: ='ceasumm_raw_results (260519)'!U9002 -> 88343829 | S15: ='ceasumm_raw_results (260519)'!V9002 -> 85133843 | T15: ='ceasumm_raw_results (260519)'!W9002 -> 90125452 | U15: =T$13-T15 -> 3227951.8
A16: IND | B16: SCRhi | C16: ='Currencies & CETs'!F18 -> 2.1690362e+13 | D16: ='ceasumm_raw_results (260519)'!O7002 -> 2.6199254e+11 | E16: =D16-D$13 -> 2.440768e+11 | F16: ='ceasumm_raw_results (260519)'!T7002 -> 62119515 | G16: =F$13-F16 -> 29081144 | H16: =E16/G16 -> 8392.9571 | I16: ='ceasumm_raw_results (260519)'!AA7002 -> 0 | J16: ='ceasumm_raw_results (260519)'!AB7002 -> 0 | L16: ='ceasumm_raw_results (260519)'!P7002 -> 2.5949477e+11 | M16: ='ceasumm_raw_results (260519)'!Q7002 -> 1.6573205e+11 | N16: ='ceasumm_raw_results (260519)'!R7002 -> 3.7015359e+11 | O16: =N16-N$13 -> 3.4451472e+11 | P16: ='ceasumm_raw_results (260519)'!S7002 -> 2.4149263e+11 | R16: ='ceasumm_raw_results (260519)'!U7002 -> 62292009 | S16: ='ceasumm_raw_results (260519)'!V7002 -> 59578511 | T16: ='ceasumm_raw_results (260519)'!W7002 -> 64796972 | U16: =T$13-T16 -> 28556432
A17: IND | B17: SCRlo | C17: ='Currencies & CETs'!F19 -> 4.0644245e+12 | D17: ='ceasumm_raw_results (260519)'!O7502 -> 4.9093181e+10 | E17: =D17-D$13 -> 3.1177441e+10 | F17: ='ceasumm_raw_results (260519)'!T7502 -> 62119515 | G17: =F$13-F17 -> 29081144 | H17: =E17/G17 -> 1072.0844 | I17: ='ceasumm_raw_results (260519)'!AA7502 -> 0 | J17: ='ceasumm_raw_results (260519)'!AB7502 -> 0 | L17: ='ceasumm_raw_results (260519)'!P7502 -> 4.9066775e+10 | M17: ='ceasumm_raw_results (260519)'!Q7502 -> 3.6586635e+10 | N17: ='ceasumm_raw_results (260519)'!R7502 -> 6.3670786e+10 | O17: =N17-N$13 -> 3.8031918e+10 | P17: ='ceasumm_raw_results (260519)'!S7502 -> 3.093283e+10 | R17: ='ceasumm_raw_results (260519)'!U7502 -> 62292009 | S17: ='ceasumm_raw_results (260519)'!V7502 -> 59578511 | T17: ='ceasumm_raw_results (260519)'!W7502 -> 64796972 | U17: =T$13-T17 -> 28556432
A18: IND | B18: DGN | C18: ='Currencies & CETs'!F20 -> 2.4367718e+12 | D18: ='ceasumm_raw_results (260519)'!O5502 -> 2.9433166e+10 | E18: =D18-D$13 -> 1.1517426e+10 | F18: ='ceasumm_raw_results (260519)'!T5502 -> 90329130 | G18: =F$13-F18 -> 871529.19 | H18: =E18/G18 -> 13215.193 | I18: ='ceasumm_raw_results (260519)'!AA5502 -> 0.018 | J18: ='ceasumm_raw_results (260519)'!AB5502 -> 0.02 | L18: ='ceasumm_raw_results (260519)'!P5502 -> 2.9004368e+10 | M18: ='ceasumm_raw_results (260519)'!Q5502 -> 2.0411567e+10 | N18: ='ceasumm_raw_results (260519)'!R5502 -> 4.3151191e+10 | O18: =N18-N$13 -> 1.7512323e+10 | P18: ='ceasumm_raw_results (260519)'!S5502 -> 1.1151957e+10 | R18: ='ceasumm_raw_results (260519)'!U5502 -> 90581891 | S18: ='ceasumm_raw_results (260519)'!V5502 -> 87355466 | T18: ='ceasumm_raw_results (260519)'!W5502 -> 92452714 | U18: =T$13-T18 -> 900690.26
A19: IND | B19: DST | C19: ='Currencies & CETs'!F21 -> 1.5465573e+12 | D19: ='ceasumm_raw_results (260519)'!O6002 -> 1.8680484e+10 | E19: =D19-D$13 -> 7.6474426e+08 | F19: ='ceasumm_raw_results (260519)'!T6002 -> 90093481 | G19: =F$13-F19 -> 1107179 | H19: =E19/G19 -> 690.71417 | I19: ='ceasumm_raw_results (260519)'!AA6002 -> 0.024 | J19: ='ceasumm_raw_results (260519)'!AB6002 -> 0.242 | L19: ='ceasumm_raw_results (260519)'!P6002 -> 1.8312355e+10 | M19: ='ceasumm_raw_results (260519)'!Q6002 -> 1.2956214e+10 | N19: ='ceasumm_raw_results (260519)'!R6002 -> 2.6543859e+10 | O19: =N19-N$13 -> 9.0499157e+08 | P19: ='ceasumm_raw_results (260519)'!S6002 -> 7.4735931e+08 | R19: ='ceasumm_raw_results (260519)'!U6002 -> 90345931 | S19: ='ceasumm_raw_results (260519)'!V6002 -> 87080497 | T19: ='ceasumm_raw_results (260519)'!W6002 -> 92294936 | U19: =T$13-T19 -> 1058468.3
A20: IND | B20: SDS | C20: ='Currencies & CETs'!F22 -> 1.6028838e+12 | D20: ='ceasumm_raw_results (260519)'!O8502 -> 1.9360839e+10 | E20: =D20-D$13 -> 1.445099e+09 | F20: ='ceasumm_raw_results (260519)'!T8502 -> 91200660 | G20: =F$13-F20 -> 0 | H20: =E20/G20 -> #DIV/0! | I20: ='ceasumm_raw_results (260519)'!AA8502 -> 0 | J20: ='ceasumm_raw_results (260519)'!AB8502 -> 0 | L20: ='ceasumm_raw_results (260519)'!P8502 -> 1.9119314e+10 | M20: ='ceasumm_raw_results (260519)'!Q8502 -> 1.327531e+10 | N20: ='ceasumm_raw_results (260519)'!R8502 -> 2.7373753e+10 | O20: =N20-N$13 -> 1.7348852e+09 | P20: ='ceasumm_raw_results (260519)'!S8502 -> 1.474791e+09 | R20: ='ceasumm_raw_results (260519)'!U8502 -> 91456960 | S20: ='ceasumm_raw_results (260519)'!V8502 -> 88194081 | T20: ='ceasumm_raw_results (260519)'!W8502 -> 93353404 | U20: =T$13-T20 -> 0
A21: IND | B21: SDR | C21: ='Currencies & CETs'!F23 -> 1.4577378e+12 | D21: ='ceasumm_raw_results (260519)'!O8002 -> 1.7607656e+10 | E21: =D21-D$13 -> -3.080837e+08 | F21: ='ceasumm_raw_results (260519)'!T8002 -> 89095112 | G21: =F$13-F21 -> 2105548 | H21: =E21/G21 -> -146.31997 | I21: ='ceasumm_raw_results (260519)'!AA8002 -> 1 | J21: ='ceasumm_raw_results (260519)'!AB8002 -> 1 | L21: ='ceasumm_raw_results (260519)'!P8002 -> 1.7223452e+10 | M21: ='ceasumm_raw_results (260519)'!Q8002 -> 1.2049099e+10 | N21: ='ceasumm_raw_results (260519)'!R8002 -> 2.5237975e+10 | O21: =N21-N$13 -> -4.0089288e+08 | P21: ='ceasumm_raw_results (260519)'!S8002 -> -3.0205062e+08 | R21: ='ceasumm_raw_results (260519)'!U8002 -> 89345505 | S21: ='ceasumm_raw_results (260519)'!V8002 -> 86037948 | T21: ='ceasumm_raw_results (260519)'!W8002 -> 91351471 | U21: =T$13-T21 -> 2001933.5
A22: IND | B22: NTN | C22: ='Currencies & CETs'!F24 -> 1.6700739e+12 | D22: ='ceasumm_raw_results (260519)'!O6502 -> 2.0172411e+10 | E22: =D22-D$13 -> 2.2566712e+09 | F22: ='ceasumm_raw_results (260519)'!T6502 -> 83169247 | G22: =F$13-F22 -> 8031413.1 | H22: =E22/G22 -> 280.98058 | I22: ='ceasumm_raw_results (260519)'!AA6502 -> 0.986 | J22: ='ceasumm_raw_results (260519)'!AB6502 -> 1 | L22: ='ceasumm_raw_results (260519)'!P6502 -> 1.9736236e+10 | M22: ='ceasumm_raw_results (260519)'!Q6502 -> 1.4528995e+10 | N22: ='ceasumm_raw_results (260519)'!R6502 -> 2.7980551e+10 | O22: =N22-N$13 -> 2.3416832e+09 | P22: ='ceasumm_raw_results (260519)'!S6502 -> 2.230863e+09 | R22: ='ceasumm_raw_results (260519)'!U6502 -> 83394879 | S22: ='ceasumm_raw_results (260519)'!V6502 -> 80200825 | T22: ='ceasumm_raw_results (260519)'!W6502 -> 85283934 | U22: =T$13-T22 -> 8069470.3
C23: Mean cost (R) | O23: =O17/O16 -> 0.11039272 | P23: =P17/P16 -> 0.12809016
A24: ZAF | B24: BAU | C24: ='Currencies & CETs'!F26 -> 4.7218304e+10 | D24: ='ceasumm_raw_results (260519)'!O10002 -> 2.5592577e+09 | F24: ='ceasumm_raw_results (260519)'!T10002 -> 14761247 | L24: ='ceasumm_raw_results (260519)'!P10002 -> 2.5044683e+09 | M24: ='ceasumm_raw_results (260519)'!Q10002 -> 1.6713628e+09 | N24: ='ceasumm_raw_results (260519)'!R10002 -> 3.5755612e+09 | P24: ='ceasumm_raw_results (260519)'!S10002 -> 0 | R24: ='ceasumm_raw_results (260519)'!U10002 -> 14793220 | S24: ='ceasumm_raw_results (260519)'!V10002 -> 13360800 | T24: ='ceasumm_raw_results (260519)'!W10002 -> 15973833
A25: ZAF | B25: VAX | C25: ='Currencies & CETs'!F27 -> 5.790389e+10 | D25: ='ceasumm_raw_results (260519)'!O14002 -> 3.1384222e+09 | E25: =D25-D$24 -> 5.7916455e+08 | F25: ='ceasumm_raw_results (260519)'!T14002 -> 11802831 | G25: =F$24-F25 -> 2958415.6 | H25: =E25/G25 -> 195.76849 | I25: ='ceasumm_raw_results (260519)'!AA14002 -> 1 | J25: ='ceasumm_raw_results (260519)'!AB14002 -> 1 | L25: ='ceasumm_raw_results (260519)'!P14002 -> 3.1110962e+09 | M25: ='ceasumm_raw_results (260519)'!Q14002 -> 2.178402e+09 | N25: ='ceasumm_raw_results (260519)'!R14002 -> 4.1747343e+09 | O25: =N25-N$24 -> 5.9917312e+08 | P25: ='ceasumm_raw_results (260519)'!S14002 -> 5.6588626e+08 | R25: ='ceasumm_raw_results (260519)'!U14002 -> 11812547 | S25: ='ceasumm_raw_results (260519)'!V14002 -> 10626017 | T25: ='ceasumm_raw_results (260519)'!W14002 -> 12789241 | U25: =T$24-T25 -> 3184592
A26: ZAF | B26: TPT | C26: ='Currencies & CETs'!F28 -> 5.0177749e+10 | D26: ='ceasumm_raw_results (260519)'!O13502 -> 2.7196612e+09 | E26: =D26-D$24 -> 1.6040351e+08 | F26: ='ceasumm_raw_results (260519)'!T13502 -> 14317578 | G26: =F$24-F26 -> 443668.96 | H26: =E26/G26 -> 361.53873 | I26: ='ceasumm_raw_results (260519)'!AA13502 -> 1 | J26: ='ceasumm_raw_results (260519)'!AB13502 -> 1 | L26: ='ceasumm_raw_results (260519)'!P13502 -> 2.6694795e+09 | M26: ='ceasumm_raw_results (260519)'!Q13502 -> 1.8445079e+09 | N26: ='ceasumm_raw_results (260519)'!R13502 -> 3.7151881e+09 | O26: =N26-N$24 -> 1.396269e+08 | P26: ='ceasumm_raw_results (260519)'!S13502 -> 1.5812191e+08 | R26: ='ceasumm_raw_results (260519)'!U13502 -> 14348320 | S26: ='ceasumm_raw_results (260519)'!V13502 -> 12980389 | T26: ='ceasumm_raw_results (260519)'!W13502 -> 15499399 | U26: =T$24-T26 -> 474434.19
A27: ZAF | B27: SCRhi | C27: ='Currencies & CETs'!F29 -> 2.2712405e+11 | D27: ='ceasumm_raw_results (260519)'!O11502 -> 1.2310247e+10 | E27: =D27-D$24 -> 9.7509891e+09 | F27: ='ceasumm_raw_results (260519)'!T11502 -> 10232280 | G27: =F$24-F27 -> 4528966.8 | H27: =E27/G27 -> 2153.0273 | I27: ='ceasumm_raw_results (260519)'!AA11502 -> 0.722 | J27: ='ceasumm_raw_results (260519)'!AB11502 -> 0.966 | L27: ='ceasumm_raw_results (260519)'!P11502 -> 1.200923e+10 | M27: ='ceasumm_raw_results (260519)'!Q11502 -> 8.441124e+09 | N27: ='ceasumm_raw_results (260519)'!R11502 -> 1.7464241e+10 | O27: =N27-N$24 -> 1.388868e+10 | P27: ='ceasumm_raw_results (260519)'!S11502 -> 9.4215573e+09 | R27: ='ceasumm_raw_results (260519)'!U11502 -> 10263525 | S27: ='ceasumm_raw_results (260519)'!V11502 -> 9245608.8 | T27: ='ceasumm_raw_results (260519)'!W11502 -> 11088156 | U27: =T$24-T27 -> 4885677.4
A28: ZAF | B28: SCRlo | C28: ='Currencies & CETs'!F30 -> 8.2802365e+10 | D28: ='ceasumm_raw_results (260519)'!O12002 -> 4.4879331e+09 | E28: =D28-D$24 -> 1.9286754e+09 | F28: ='ceasumm_raw_results (260519)'!T12002 -> 10232280 | G28: =F$24-F28 -> 4528966.8 | H28: =E28/G28 -> 425.85328 | I28: ='ceasumm_raw_results (260519)'!AA12002 -> 1 | J28: ='ceasumm_raw_results (260519)'!AB12002 -> 1 | L28: ='ceasumm_raw_results (260519)'!P12002 -> 4.4553526e+09 | M28: ='ceasumm_raw_results (260519)'!Q12002 -> 3.3896125e+09 | N28: ='ceasumm_raw_results (260519)'!R12002 -> 5.7730457e+09 | O28: =N28-N$24 -> 2.1974845e+09 | P28: ='ceasumm_raw_results (260519)'!S12002 -> 1.9047404e+09 | R28: ='ceasumm_raw_results (260519)'!U12002 -> 10263525 | S28: ='ceasumm_raw_results (260519)'!V12002 -> 9245608.8 | T28: ='ceasumm_raw_results (260519)'!W12002 -> 11088156 | U28: =T$24-T28 -> 4885677.4
A29: ZAF | B29: DGN | C29: ='Currencies & CETs'!F31 -> 5.0464091e+10 | D29: ='ceasumm_raw_results (260519)'!O10502 -> 2.7351811e+09 | E29: =D29-D$24 -> 1.7592343e+08 | F29: ='ceasumm_raw_results (260519)'!T10502 -> 14547715 | G29: =F$24-F29 -> 213532.42 | H29: =E29/G29 -> 823.87223 | I29: ='ceasumm_raw_results (260519)'!AA10502 -> 0.752 | J29: ='ceasumm_raw_results (260519)'!AB10502 -> 0.834 | L29: ='ceasumm_raw_results (260519)'!P10502 -> 2.7010273e+09 | M29: ='ceasumm_raw_results (260519)'!Q10502 -> 1.9023522e+09 | N29: ='ceasumm_raw_results (260519)'!R10502 -> 3.7003371e+09 | O29: =N29-N$24 -> 1.2477589e+08 | P29: ='ceasumm_raw_results (260519)'!S10502 -> 1.6996604e+08 | R29: ='ceasumm_raw_results (260519)'!U10502 -> 14582803 | S29: ='ceasumm_raw_results (260519)'!V10502 -> 13173720 | T29: ='ceasumm_raw_results (260519)'!W10502 -> 15735360 | U29: =T$24-T29 -> 238472.92
A30: ZAF | B30: DST | C30: ='Currencies & CETs'!F32 -> 4.7619297e+10 | D30: ='ceasumm_raw_results (260519)'!O11002 -> 2.5809917e+09 | E30: =D30-D$24 -> 21734011 | F30: ='ceasumm_raw_results (260519)'!T11002 -> 14672804 | G30: =F$24-F30 -> 88443.325 | H30: =E30/G30 -> 245.73942 | I30: ='ceasumm_raw_results (260519)'!AA11002 -> 1 | J30: ='ceasumm_raw_results (260519)'!AB11002 -> 1 | L30: ='ceasumm_raw_results (260519)'!P11002 -> 2.5210277e+09 | M30: ='ceasumm_raw_results (260519)'!Q11002 -> 1.6931872e+09 | N30: ='ceasumm_raw_results (260519)'!R11002 -> 3.5948812e+09 | O30: =N30-N$24 -> 19320021 | P30: ='ceasumm_raw_results (260519)'!S11002 -> 21184994 | R30: ='ceasumm_raw_results (260519)'!U11002 -> 14706567 | S30: ='ceasumm_raw_results (260519)'!V11002 -> 13273774 | T30: ='ceasumm_raw_results (260519)'!W11002 -> 15867992 | U30: =T$24-T30 -> 105840.98
A31: ZAF | B31: SDS | C31: ='Currencies & CETs'!F33 -> 4.8814238e+10 | D31: ='ceasumm_raw_results (260519)'!O13002 -> 2.6457582e+09 | E31: =D31-D$24 -> 86500496 | F31: ='ceasumm_raw_results (260519)'!T13002 -> 14761247 | G31: =F$24-F31 -> 0 | H31: =E31/G31 -> #DIV/0! | I31: ='ceasumm_raw_results (260519)'!AA13002 -> 0 | J31: ='ceasumm_raw_results (260519)'!AB13002 -> 0 | L31: ='ceasumm_raw_results (260519)'!P13002 -> 2.6142426e+09 | M31: ='ceasumm_raw_results (260519)'!Q13002 -> 1.7375056e+09 | N31: ='ceasumm_raw_results (260519)'!R13002 -> 3.6806081e+09 | O31: =N31-N$24 -> 1.0504689e+08 | P31: ='ceasumm_raw_results (260519)'!S13002 -> 83220867 | R31: ='ceasumm_raw_results (260519)'!U13002 -> 14793220 | S31: ='ceasumm_raw_results (260519)'!V13002 -> 13360800 | T31: ='ceasumm_raw_results (260519)'!W13002 -> 15973833 | U31: =T$24-T31 -> 0
A32: ZAF | B32: SDR | C32: ='Currencies & CETs'!F34 -> 4.6533732e+10 | D32: ='ceasumm_raw_results (260519)'!O12502 -> 2.5221535e+09 | E32: =D32-D$24 -> -37104160 | F32: ='ceasumm_raw_results (260519)'!T12502 -> 14572727 | G32: =F$24-F32 -> 188519.68 | H32: =E32/G32 -> -196.8185 | I32: ='ceasumm_raw_results (260519)'!AA12502 -> 1 | J32: ='ceasumm_raw_results (260519)'!AB12502 -> 1 | L32: ='ceasumm_raw_results (260519)'!P12502 -> 2.479236e+09 | M32: ='ceasumm_raw_results (260519)'!Q12502 -> 1.6342374e+09 | N32: ='ceasumm_raw_results (260519)'!R12502 -> 3.542131e+09 | O32: =N32-N$24 -> -33430163 | P32: ='ceasumm_raw_results (260519)'!S12502 -> -35420560 | R32: ='ceasumm_raw_results (260519)'!U12502 -> 14604988 | S32: ='ceasumm_raw_results (260519)'!V12502 -> 13180938 | T32: ='ceasumm_raw_results (260519)'!W12502 -> 15745057 | U32: =T$24-T32 -> 228776.64
O33: =O28/O27 -> 0.15822126 | P33: =P28/P27 -> 0.20216832

Sheet Tables
A1: 3.3a
A2: BRAZIL | B2: Intervention | C2: Mean total cost (billion R$) | D2: Mean total cost (billion US$) | E2: Incremental cost compared to BAU (million US$) | F2: Mean total DALYs (million) | G2: DALYs averted compared to BAU (million) | H2: ICER compared to BAU (US$ per DALY averted) | I2: Probability cost-effective at lower end of threshold range (US$6,968 per DALY) | J2: Probability cost-effective at upper end of threshold range (US$10,735 per DALY)
B3: Business as usual | C3: =Summaries!C2/1000000000 -> 8.0397031 | D3: =Summaries!D2/1000000000 -> 1.6111629 | E3: - | F3: =Summaries!F2/1000000 -> 6.4897236 | G3: - | H3: - | I3: - | J3: -
B4: Vaccination | C4: =Summaries!C3/1000000000 -> 19.778932 | D4: =Summaries!D3/1000000000 -> 3.9637137 | E4: =Summaries!E3/1000000 -> 2352.5508 | F4: =Summaries!F3/1000000 -> 5.0027748 | G4: =Summaries!G3/1000000 -> 1.4869487 | H4: =Summaries!H3 -> 1582.1331 | I4: =Summaries!I3 -> 1 | J4: =Summaries!J3 -> 1
B5: TB preventive treatment | C5: =Summaries!C4/1000000000 -> 8.291257 | D5: =Summaries!D4/1000000000 -> 1.6615746 | E5: =Summaries!E4/1000000 -> 50.411611 | F5: =Summaries!F4/1000000 -> 6.4266373 | G5: =Summaries!G4/1000000 -> 0.063086293 | H5: =Summaries!H4 -> 799.08977 | I5: =Summaries!I4 -> 1 | J5: =Summaries!J4 -> 1
B6: Community screening (high-cost) | C6: =Summaries!C5/1000000000 -> 192.29125 | D6: =Summaries!D5/1000000000 -> 38.53532 | E6: =Summaries!E5/1000000 -> 36924.157 | F6: =Summaries!F5/1000000 -> 3.9031616 | G6: =Summaries!G5/1000000 -> 2.5865619 | H6: =Summaries!H5 -> 14275.381 | I6: =Summaries!I5 -> 0.008 | J6: =Summaries!J5 -> 0.182
B7: Community screening (low-cost) | C7: =Summaries!C6/1000000000 -> 40.424882 | D7: =Summaries!D6/1000000000 -> 8.1011788 | E7: =Summaries!E6/1000000 -> 6490.0159 | F7: =Summaries!F6/1000000 -> 3.9031616 | G7: =Summaries!G6/1000000 -> 2.5865619 | H7: =Summaries!H6 -> 2509.1283 | I7: =Summaries!I6 -> 1 | J7: =Summaries!J6 -> 1
B8: Improved diagnosis | C8: =Summaries!C7/1000000000 -> 10.894149 | D8: =Summaries!D7/1000000000 -> 2.1831962 | E8: =Summaries!E7/1000000 -> 572.03329 | F8: =Summaries!F7/1000000 -> 6.3499128 | G8: =Summaries!G7/1000000 -> 0.13981072 | H8: =Summaries!H7 -> 4091.4838 | I8: =Summaries!I7 -> 0.808 | J8: =Summaries!J7 -> 0.922
B9: Drug susceptibility testing for all | C9: =Summaries!C8/1000000000 -> 9.2705148 | D9: =Summaries!D8/1000000000 -> 1.8578186 | E9: =Summaries!E8/1000000 -> 246.65566 | F9: =Summaries!F8/1000000 -> 6.3770852 | G9: =Summaries!G8/1000000 -> 0.1126384 | H9: =Summaries!H8 -> 2189.8008 | I9: =Summaries!I8 -> 1 | J9: =Summaries!J8 -> 1
B10: Shorter DS-TB treatment | C10: =Summaries!C9/1000000000 -> 8.5291709 | D10: =Summaries!D9/1000000000 -> 1.7092527 | E10: =Summaries!E9/1000000 -> 98.08975 | F10: =Summaries!F9/1000000 -> 6.4897236 | G10: =Summaries!G9/1000000 -> 0 | H10: =IF(Summaries!G9=0,"Dominated by BAU",Summaries!H9) -> Dominated by BAU | I10: =Summaries!I9 -> 0 | J10: =Summaries!J9 -> 0
B11: Shorter DR-TB treatment | C11: =Summaries!C10/1000000000 -> 6.3607333 | D11: =Summaries!D10/1000000000 -> 1.274696 | E11: =Summaries!E10/1000000 -> -336.4669 | F11: =Summaries!F10/1000000 -> 6.3792249 | G11: =Summaries!G10/1000000 -> 0.11049864 | H11: =IF(Summaries!H10<0,"Dominates BAU",Summaries!H10) -> Dominates BAU | I11: =Summaries!I10 -> 1 | J11: =Summaries!J10 -> 1
B12: Screening in prisons | C12: =Summaries!C11/1000000000 -> 8.9914634 | D12: =Summaries!D11/1000000000 -> 1.8018965 | E12: =Summaries!E11/1000000 -> 190.73354 | F12: =Summaries!F11/1000000 -> 5.1854626 | G12: =Summaries!G11/1000000 -> 1.304261 | H12: =Summaries!H11 -> 146.23878 | I12: =Summaries!I11 -> 1 | J12: =Summaries!J11 -> 1
A13: 3.3b
A14: INDIA | B14: Intervention | C14: Mean total cost (trillion INR) | D14: Mean total cost (billion US$) | E14: Incremental cost compared to BAU (billion US$) | F14: Mean total DALYs (million) | G14: DALYs averted compared to BAU (million) | H14: ICER compared to BAU (US$ per DALY averted) | I14: Probability cost-effective at lower end of threshold range (US$413 per DALY) | J14: Probability cost-effective at upper end of threshold range (US$569 per DALY)
B15: Business as usual | C15: =Summaries!C13/1000000000000 -> 1.4832441 | D15: =Summaries!D13/1000000000 -> 17.91574 | E15: - | F15: =Summaries!F13/1000000 -> 91.20066 | G15: - | H15: - | I15: - | J15: -
B16: Vaccination | C16: =Summaries!C14/1000000000000 -> 2.7718347 | D16: =Summaries!D14/1000000000 -> 33.480308 | E16: =Summaries!E14/1000000000 -> 15.564568 | F16: =Summaries!F14/1000000 -> 80.713121 | G16: =Summaries!G14/1000000 -> 10.487539 | H16: =Summaries!H14 -> 1484.1011 | I16: =Summaries!I14 -> 0 | J16: =Summaries!J14 -> 0.002
B17: TB preventive treatment | C17: =Summaries!C15/1000000000000 -> 1.584983 | D17: =Summaries!D15/1000000000 -> 19.144619 | E17: =Summaries!E15/1000000000 -> 1.2288796 | F17: =Summaries!F15/1000000 -> 88.084845 | G17: =Summaries!G15/1000000 -> 3.1158149 | H17: =Summaries!H15 -> 394.40071 | I17: =Summaries!I15 -> 0.628 | J17: =Summaries!J15 -> 0.976
B18: Community screening (high-cost) | C18: =Summaries!C16/1000000000000 -> 21.690362 | D18: =Summaries!D16/1000000000 -> 261.99254 | E18: =Summaries!E16/1000000000 -> 244.0768 | F18: =Summaries!F16/1000000 -> 62.119515 | G18: =Summaries!G16/1000000 -> 29.081144 | H18: =Summaries!H16 -> 8392.9571 | I18: =Summaries!I16 -> 0 | J18: =Summaries!J16 -> 0
B19: Community screening (low-cost) | C19: =Summaries!C17/1000000000000 -> 4.0644245 | D19: =Summaries!D17/1000000000 -> 49.093181 | E19: =Summaries!E17/1000000000 -> 31.177441 | F19: =Summaries!F17/1000000 -> 62.119515 | G19: =Summaries!G17/1000000 -> 29.081144 | H19: =Summaries!H17 -> 1072.0844 | I19: =Summaries!I17 -> 0 | J19: =Summaries!J17 -> 0
B20: Improved diagnosis | C20: =Summaries!C18/1000000000000 -> 2.4367718 | D20: =Summaries!D18/1000000000 -> 29.433166 | E20: =Summaries!E18/1000000000 -> 11.517426 | F20: =Summaries!F18/1000000 -> 90.32913 | G20: =Summaries!G18/1000000 -> 0.87152919 | H20: =Summaries!H18 -> 13215.193 | I20: =Summaries!I18 -> 0.018 | J20: =Summaries!J18 -> 0.02
B21: Drug susceptibility testing for all | C21: =Summaries!C19/1000000000000 -> 1.5465573 | D21: =Summaries!D19/1000000000 -> 18.680484 | E21: =Summaries!E19/1000000000 -> 0.76474426 | F21: =Summaries!F19/1000000 -> 90.093481 | G21: =Summaries!G19/1000000 -> 1.107179 | H21: =Summaries!H19 -> 690.71417 | I21: =Summaries!I19 -> 0.024 | J21: =Summaries!J19 -> 0.242
B22: Shorter DS-TB treatment | C22: =Summaries!C20/1000000000000 -> 1.6028838 | D22: =Summaries!D20/1000000000 -> 19.360839 | E22: =Summaries!E20/1000000000 -> 1.445099 | F22: =Summaries!F20/1000000 -> 91.20066 | G22: =Summaries!G20/1000000 -> 0 | H22: =IF(Summaries!G20=0,"Dominated by BAU",Summaries!H20) -> Dominated by BAU | I22: =Summaries!I20 -> 0 | J22: =Summaries!J20 -> 0
B23: Shorter DR-TB treatment | C23: =Summaries!C21/1000000000000 -> 1.4577378 | D23: =Summaries!D21/1000000000 -> 17.607656 | E23: =Summaries!E21/1000000000 -> -0.3080837 | F23: =Summaries!F21/1000000 -> 89.095112 | G23: =Summaries!G21/1000000 -> 2.105548 | H23: =IF(Summaries!H21<0,"Dominates BAU",Summaries!H21) -> Dominates BAU | I23: =Summaries!I21 -> 1 | J23: =Summaries!J21 -> 1
B24: Nutrition | C24: =Summaries!C22/1000000000000 -> 1.6700739 | D24: =Summaries!D22/1000000000 -> 20.172411 | E24: =Summaries!E22/1000000000 -> 2.2566712 | F24: =Summaries!F22/1000000 -> 83.169247 | G24: =Summaries!G22/1000000 -> 8.0314131 | H24: =Summaries!H22 -> 280.98058 | I24: =Summaries!I22 -> 0.986 | J24: =Summaries!J22 -> 1
A25: 3.3c
A26: SOUTH AFRICA | B26: Intervention | C26: Mean total cost (billion R$) | D26: Mean total cost (billion US$) | E26: Incremental cost compared to BAU (million US$) | F26: Mean total DALYs (million) | G26: DALYs averted compared to BAU (million) | H26: ICER compared to BAU (US$ per DALY averted) | I26: Probability cost-effective at lower end of threshold range (US$2,444 per DALY) | J26: Probability cost-effective at upper end of threshold range (US$3,285 per DALY)
B27: Business as usual | C27: =Summaries!C24/1000000000 -> 47.218304 | D27: =Summaries!D24/1000000000 -> 2.5592577 | E27: - | F27: =Summaries!F24/1000000 -> 14.761247 | G27: - | I27: - | J27: -
B28: Vaccination | C28: =Summaries!C25/1000000000 -> 57.90389 | D28: =Summaries!D25/1000000000 -> 3.1384222 | E28: =Summaries!E25/1000000 -> 579.16455 | F28: =Summaries!F25/1000000 -> 11.802831 | G28: =Summaries!G25/1000000 -> 2.9584156 | H28: =Summaries!H25 -> 195.76849 | I28: =Summaries!I25 -> 1 | J28: =Summaries!J25 -> 1
B29: TB preventive treatment | C29: =Summaries!C26/1000000000 -> 50.177749 | D29: =Summaries!D26/1000000000 -> 2.7196612 | E29: =Summaries!E26/1000000 -> 160.40351 | F29: =Summaries!F26/1000000 -> 14.317578 | G29: =Summaries!G26/1000000 -> 0.44366896 | H29: =Summaries!H26 -> 361.53873 | I29: =Summaries!I26 -> 1 | J29: =Summaries!J26 -> 1
B30: Community screening (high-cost) | C30: =Summaries!C27/1000000000 -> 227.12405 | D30: =Summaries!D27/1000000000 -> 12.310247 | E30: =Summaries!E27/1000000 -> 9750.9891 | F30: =Summaries!F27/1000000 -> 10.23228 | G30: =Summaries!G27/1000000 -> 4.5289668 | H30: =Summaries!H27 -> 2153.0273 | I30: =Summaries!I27 -> 0.722 | J30: =Summaries!J27 -> 0.966
B31: Community screening (low-cost) | C31: =Summaries!C28/1000000000 -> 82.802365 | D31: =Summaries!D28/1000000000 -> 4.4879331 | E31: =Summaries!E28/1000000 -> 1928.6754 | F31: =Summaries!F28/1000000 -> 10.23228 | G31: =Summaries!G28/1000000 -> 4.5289668 | H31: =Summaries!H28 -> 425.85328 | I31: =Summaries!I28 -> 1 | J31: =Summaries!J28 -> 1
B32: Improved diagnosis | C32: =Summaries!C29/1000000000 -> 50.464091 | D32: =Summaries!D29/1000000000 -> 2.7351811 | E32: =Summaries!E29/1000000 -> 175.92343 | F32: =Summaries!F29/1000000 -> 14.547715 | G32: =Summaries!G29/1000000 -> 0.21353242 | H32: =Summaries!H29 -> 823.87223 | I32: =Summaries!I29 -> 0.752 | J32: =Summaries!J29 -> 0.834
B33: Drug susceptibility testing for all | C33: =Summaries!C30/1000000000 -> 47.619297 | D33: =Summaries!D30/1000000000 -> 2.5809917 | E33: =Summaries!E30/1000000 -> 21.734011 | F33: =Summaries!F30/1000000 -> 14.672804 | G33: =Summaries!G30/1000000 -> 0.088443325 | H33: =Summaries!H30 -> 245.73942 | I33: =Summaries!I30 -> 1 | J33: =Summaries!J30 -> 1
B34: Shorter DS-TB treatment | C34: =Summaries!C31/1000000000 -> 48.814238 | D34: =Summaries!D31/1000000000 -> 2.6457582 | E34: =Summaries!E31/1000000 -> 86.500496 | F34: =Summaries!F31/1000000 -> 14.761247 | G34: =Summaries!G31/1000000 -> 0 | H34: =IF(Summaries!G31=0,"Dominated by BAU",Summaries!H31) -> Dominated by BAU | I34: =Summaries!I31 -> 0 | J34: =Summaries!J31 -> 0
B35: Shorter DR-TB treatment | C35: =Summaries!C32/1000000000 -> 46.533732 | D35: =Summaries!D32/1000000000 -> 2.5221535 | E35: =Summaries!E32/1000000 -> -37.10416 | F35: =Summaries!F32/1000000 -> 14.572727 | G35: =Summaries!G32/1000000 -> 0.18851968 | H35: =IF(Summaries!H32<0,"Dominates BAU",Summaries!H32) -> Dominates BAU | I35: =Summaries!I32 -> 1 | J35: =Summaries!J32 -> 1
