Workbook
Name BRA_cet_high: VALUES!$D$19
Name BRA_cet_low: VALUES!$D$18
Name BRA_disc: VALUES!$D$23
Name BRA_disc_factor: VALUES!$D$24
Name disc: VALUES!$G$23
Name disc_factor: VALUES!$G$24
Name IND_cet_high: VALUES!$E$19
Name IND_cet_low: VALUES!$E$18
Name IND_disc: VALUES!$E$23
Name IND_disc_factor: VALUES!$E$24
Name ZAF_cet_high: VALUES!$F$19
Name ZAF_cet_low: VALUES!$F$18
Name ZAF_disc: VALUES!$F$23
Name ZAF_disc_factor: VALUES!$F$24

Sheet VALUES
A1: TABLES containing numerical values to read to R
A3: ECONOMIC PARAMETERS for all analyses
B5: Parameter | C5: Parameter name
A6: Disability weights | D6: BRA | E6: IND | F6: ZAF
B7: Clinical TB | C7: dw_TB | D7: 0.333 | E7: 0.333 | F7: 0.333
B8: Post-TB | C8: dw_postTB | D8: 0.036 | E8: 0.036 | F8: 0.036
A10: Utility weights
D11: BRA | E11: IND | F11: ZAF
B12: No TB/TB infection | C12: u_healthy | D12: 1 | E12: 1 | F12: 1
B13: Clinical TB | C13: u_TB | D13: =F13 -> 0.62 | E13: 0.56 | F13: 0.62
B14: Post-TB | C14: u_postTB | D14: =1-D8 -> 0.964 | E14: =1-E8 -> 0.964 | F14: =1-F8 -> 0.964
A16: Cost-effectiveness thresholds
D17: BRA | E17: IND | F17: ZAF
B18: Low CET | C18: cet_low | D18: 6967.5452 | E18: 413.46583 | F18: 2443.5923
B19: Hight CET | C19: cet_high | D19: 10734.72 | E19: 568.51551 | F19: 3285.0552
A21: Discount rates
D22: BRA | E22: IND | F22: ZAF | G22: ALL
B23: Discount rate (for costs and benefits) | C23: disc | D23: 0.05 | E23: 0.05 | F23: 0.05 | G23: 0.05
B24: Discount formula | C24: disc_factor | D24: =1/(1+BRA_disc) -> 0.95238095 | E24: =1/(1+IND_disc) -> 0.95238095 | F24: =1/(1+ZAF_disc) -> 0.95238095 | G24: =1/(1+disc) -> 0.95238095
A27: COSTS per activity
B28: compiled from unit costs and resource use
D29: BRA | E29: IND | F29: ZAF
B30: Vaccination | C30: c_a_vax | D30: 10.47 | E30: 10.47 | F30: 10.47
B31: HHCM assessment | C31: c_a_HHCM | D31: 23.85834 | E31: 32.160607 | F31: 36.881511
B32: TPT for DS-TB | C32: c_a_TPT_DS | D32: 22.240677 | E32: 35.428357 | F32: 84.043957
B33: TPT for DR-TB | C33: c_a_TPT_DR | D33: 41.13638 | E33: 64.21482 | F33: 149.29212
B34: Nutrition for TB patients | C34: c_a_nutrition_index | D34: 0 | E34: 16.526694 | F34: 0
B35: Nutrition for household contacts | C35: c_a_nutrition_contact | D35: 0 | E35: 5.9679727 | F35: 0
B36: Community screening CXR (high cost estimate) | C36: c_a_screen_CXR_hi | D36: 41.395527 | E36: 41.395527 | F36: 41.395527
B37: Community screening CXR (low cost estimate) | C37: c_a_screen_CXR_lo | D37: 5.3600174 | E37: 2.4253472 | F37: 5.3600174
B38: Community screening Xpert | C38: c_a_screen_Xpert | D38: 19.36 | E38: 24.365347 | F38: 16.932351
B39: Clinic diagnosis - standard | C39: c_a_diag_standard | D39: 16.538627 | E39: 13.312165 | F39: 30.848618
B40: Clinic diagnosis - improved | C40: c_a_diag_improved | D40: 23.85834 | E40: 32.160607 | F40: 36.881511
B41: Drug sensitivity testing | C41: c_a_DST | D41: 19.36 | E41: 24.365347 | F41: 16.932351
... B46: Prison screening | C46: c_a_prison | D46: 21.516777 | E46: 0 | F46: 0
A49: LIFE YEAR calculations
B50: Healthy life expectancy (discounted) | G50: Post-TB life expectancy (discounted) | L50: LY lost through post-TB (discounted)
C51: BRA | D51: IND | E51: ZAF | H51: BRA | I51: IND | J51: ZAF | M51: BRA | N51: IND | O51: ZAF
B52: LY_healthy_y1_ag1 | C52: =LE_BRA!C4 -> 19.657236 | D52: =LE_IND!C4 -> 19.450539 | E52: =LE_ZAF!C4 -> 19.060729 | G52: LY_postTB_y1_ag1 | H52: =LE_BRA!AD4 -> 19.585419 | I52: =LE_IND!AD4 -> 19.363234 | J52: =LE_ZAF!AD4 -> 18.935661 | L52: LY_lost_postTB_y1_ag1 | M52: =C52-H52 -> 0.071817713 | N52: =D52-I52 -> 0.087304824 | O52: =E52-J52 -> 0.12506708
B53: LY_healthy_y1_ag2 | C53: =LE_BRA!C5 -> 19.464499 | D53: =LE_IND!C5 -> 19.288409 | E53: =LE_ZAF!C5 -> 18.811197 | G53: LY_postTB_y1_ag2 | H53: =LE_BRA!AD5 -> 19.378276 | I53: =LE_IND!AD5 -> 19.194228 | J53: =LE_ZAF!AD5 -> 18.671181 | L53: LY_lost_postTB_y1_ag2 | M53: =C53-H53 -> 0.08622309 | N53: =D53-I53 -> 0.094181683 | O53: =E53-J53 -> 0.14001637
...

Sheet LE_BRA
A1: LIFE EXPECTANCY | C1: BRAZIL | AC1: Mortality RR = 1.14 | AD1: (Menzies 2021)
B2: Healthy life expectancy (discounted) | C2: y1 | D2: y2 | E2: y3 | F2: y4 | G2: y5 | H2: y6 | I2: y7 | J2: y8 | K2: y9 | L2: y10 | M2: y11 | N2: y12 | O2: y13 | P2: y14 | Q2: y15 | R2: y16 | S2: y17 | T2: y18 | U2: y19 | V2: y20 | W2: y21 | X2: y22 | Y2: y23 | Z2: y24 | AA2: y25 | AC2: Post-TB life expectancy (discounted) | AD2: y1 | AE2: y2 | AF2: y3 | AG2: y4 | AH2: y5 | AI2: y6 | AJ2: y7 | AK2: y8 | AL2: y9 | AM2: y10 | AN2: y11 | AO2: y12 | AP2: y13 | AQ2: y14 | AR2: y15 | AS2: y16 | AT2: y17 | AU2: y18 | AV2: y19 | AW2: y20 | AX2: y21 | AY2: y22 | AZ2: y23 | BA2: y24 | BB2: y25
C3: 2025 | D3: 2026 | E3: 2027 | F3: 2028 | G3: 2029 | H3: 2030 | I3: 2031 | J3: 2032 | K3: 2033 | L3: 2034 | M3: 2035 | N3: 2036 | O3: 2037 | P3: 2038 | Q3: 2039 | R3: 2040 | S3: 2041 | T3: 2042 | U3: 2043 | V3: 2044 | W3: 2045 | X3: 2046 | Y3: 2047 | Z3: 2048 | AA3: 2049 | AD3: 2025 | AE3: 2026 | AF3: 2027 | AG3: 2028 | AH3: 2029 | AI3: 2030 | AJ3: 2031 | AK3: 2032 | AL3: 2033 | AM3: 2034 | AN3: 2035 | AO3: 2036 | AP3: 2037 | AQ3: 2038 | AR3: 2039 | AS3: 2040 | AT3: 2041 | AU3: 2042 | AV3: 2043 | AW3: 2044 | AX3: 2045 | AY3: 2046 | AZ3: 2047 | BA3: 2048 | BB3: 2049
B4: LY_healthy_y1_ag1 | C4: 19.657236 | D4: 19.666261 | E4: 19.675314 | F4: 19.684397 | G4: 19.693015 | H4: 19.701661 | I4: 19.710335 | J4: 19.719037 | K4: 19.727767 | L4: 19.735879 | M4: 19.744018 | N4: 19.752183 | O4: 19.760374 | P4: 19.768591 | Q4: 19.776325 | R4: 19.784082 | S4: 19.791865 | T4: 19.799673 | U4: 19.807506 | V4: 19.814771 | W4: 19.822059 | X4: 19.829371 | Y4: 19.836707 | Z4: 19.844068 | AA4: 19.85062 | AC4: LY_postTB_y1_ag1 | AD4: 19.585419 | AE4: 19.595375 | AF4: 19.605367 | AG4: 19.615392 | AH4: 19.624901 | AI4: 19.634442 | AJ4: 19.644017 | AK4: 19.653624 | AL4: 19.663265 | AM4: 19.672217 | AN4: 19.681201 | AO4: 19.690215 | AP4: 19.69926 | AQ4: 19.708337 | AR4: 19.716874 | AS4: 19.725439 | AT4: 19.734035 | AU4: 19.74266 | AV4: 19.751315 | AW4: 19.75933 | AX4: 19.767374 | AY4: 19.775446 | AZ4: 19.783546 | BA4: 19.791676 | BB4: 19.798903
B5: LY_healthy_y1_ag2 | C5: 19.464499 | D5: 19.474957 | E5: 19.485451 | F5: 19.495982 | G5: 19.506083 | H5: 19.516219 | I5: 19.526389 | J5: 19.536594 | K5: 19.546835 | L5: 19.556448 | M5: 19.566094 | N5: 19.575772 | O5: 19.585484 | P5: 19.595228 | Q5: 19.604459 | R5: 19.613722 | S5: 19.623015 | T5: 19.63234 | U5: 19.641697 | V5: 19.650425 | W5: 19.659184 | X5: 19.667972 | Y5: 19.676792 | Z5: 19.685642 | AA5: 19.693627 | AC5: LY_postTB_y1_ag2 | AD5: 19.378276 | AE5: 19.389783 | AF5: 19.401332 | AG5: 19.412924 | AH5: 19.424041 | AI5: 19.4352 | AJ5: 19.446399 | AK5: 19.457639 | AL5: 19.468922 | AM5: 19.479508 | AN5: 19.490133 | AO5: 19.500796 | AP5: 19.511498 | AQ5: 19.522239 | AR5: 19.53241 | AS5: 19.542618 | AT5: 19.552862 | AU5: 19.563144 | AV5: 19.573464 | AW5: 19.583078 | AX5: 19.592727 | AY5: 19.602413 | AZ5: 19.612134 | BA5: 19.621892 | BB5: 19.630688
B6: LY_healthy_y1_ag3 | C6: 19.202295 | D6: 19.215098 | E6: 19.227947 | F6: 19.240841 | G6: 19.253248 | H6: 19.265698 | I6: 19.278192 | J6: 19.290731 | K6: 19.303313 | L6: 19.315162 | M6: 19.327052 | N6: 19.338984 | O6: 19.350957 | P6: 19.362971 | Q6: 19.374379 | R6: 19.385825 | S6: 19.397312 | T6: 19.408838 | U6: 19.420404 | V6: 19.431217 | W6: 19.442067 | X6: 19.452956 | Y6: 19.463884 | Z6: 19.474851 | AA6: 19.484762 | AC6: LY_postTB_y1_ag3 | AD6: 19.095459 | AE6: 19.109528 | AF6: 19.123652 | AG6: 19.137829 | AH6: 19.15147 | AI6: 19.165161 | AJ6: 19.178905 | AK6: 19.1927 | AL6: 19.206548 | AM6: 19.219583 | AN6: 19.232667 | AO6: 19.2458 | AP6: 19.258982 | AQ6: 19.272213 | AR6: 19.28477 | AS6: 19.297373 | AT6: 19.310024 | AU6: 19.322721 | AV6: 19.335466 | AW6: 19.347366 | AX6: 19.35931 | AY6: 19.3713 | AZ6: 19.383336 | BA6: 19.395418 | BB6: 19.406325
B7: LY_healthy_y1_ag4 | C7: 18.899592 | D7: 18.91468 | E7: 18.929824 | F7: 18.945025 | G7: 18.959707 | H7: 18.974442 | I7: 18.989232 | J7: 19.004076 | K7: 19.018975 | L7: 19.033061 | M7: 19.047197 | N7: 19.061385 | O7: 19.075624 | P7: 19.089916 | Q7: 19.103536 | R7: 19.117205 | S7: 19.130924 | T7: 19.144692 | U7: 19.158511 | V7: 19.171476 | W7: 19.184489 | X7: 19.19755 | Y7: 19.21066 | Z7: 19.223818 | AA7: 19.235745 | AC7: LY_postTB_y1_ag4 | AD7: 18.77065 | AE7: 18.787194 | AF7: 18.803803 | AG7: 18.82048 | AH7: 18.836586 | AI7: 18.852757 | AJ7: 18.868991 | AK7: 18.885289 | AL7: 18.901653 | AM7: 18.917118 | AN7: 18.932643 | AO7: 18.948229 | AP7: 18.963875 | AQ7: 18.979583 | AR7: 18.994548 | AS7: 19.009571 | AT7: 19.024652 | AU7: 19.039792 | AV7: 19.054991 | AW7: 19.069235 | AX7: 19.083534 | AY7: 19.09789 | AZ7: 19.112304 | BA7: 19.126774 | BB7: 19.13988
B8: LY_healthy_y1_ag5 | C8: 18.578377 | D8: 18.595072 | E8: 18.611835 | F8: 18.628666 | G8: 18.644994 | H8: 18.661386 | I8: 18.677843 | J8: 18.694367 | K8: 18.710957 | L8: 18.726716 | M8: 18.742536 | N8: 18.758418 | O8: 18.774363 | P8: 18.790371 | Q8: 18.805711 | R8: 18.82111 | S8: 18.83657 | T8: 18.852089 | U8: 18.86767 | V8: 18.882383 | W8: 18.897155 | X8: 18.911985 | Y8: 18.926875 | Z8: 18.941824 | AA8: 18.955453 | AC8: LY_postTB_y1_ag5 | AD8: 18.429726 | AE8: 18.447953 | AF8: 18.466259 | AG8: 18.484646 | AH8: 18.502485 | AI8: 18.5204 | AJ8: 18.538392 | AK8: 18.556462 | AL8: 18.57461 | AM8: 18.591844 | AN8: 18.609151 | AO8: 18.626531 | AP8: 18.643985 | AQ8: 18.661513 | AR8: 18.678306 | AS8: 18.695168 | AT8: 18.712102 | AU8: 18.729106 | AV8: 18.746183 | AW8: 18.762289 | AX8: 18.778464 | AY8: 18.794708 | AZ8: 18.811022 | BA8: 18.827406 | BB8: 18.842331
B9: LY_healthy_y1_ag6 | C9: 18.198811 | D9: 18.217211 | E9: 18.235692 | F9: 18.254255 | G9: 18.272293 | H9: 18.29041 | I9: 18.308605 | J9: 18.326879 | K9: 18.345233 | L9: 18.362716 | M9: 18.380274 | N9: 18.397906 | O9: 18.415613 | P9: 18.433397 | Q9: 18.450501 | R9: 18.467677 | S9: 18.484926 | T9: 18.502247 | U9: 18.519643 | V9: 18.536176 | W9: 18.552781 | X9: 18.569457 | Y9: 18.586205 | Z9: 18.603026 | AA9: 18.618451 | AC9: LY_postTB_y1_ag6 | AD9: 18.028812 | AE9: 18.048803 | AF9: 18.068889 | AG9: 18.089071 | AH9: 18.108687 | AI9: 18.128395 | AJ9: 18.148194 | AK9: 18.168087 | AL9: 18.188073 | AM9: 18.207107 | AN9: 18.226229 | AO9: 18.245438 | AP9: 18.264735 | AQ9: 18.284122 | AR9: 18.302766 | AS9: 18.321494 | AT9: 18.340307 | AU9: 18.359207 | AV9: 18.378192 | AW9: 18.396217 | AX9: 18.414325 | AY9: 18.432516 | AZ9: 18.450792 | BA9: 18.469153 | BB9: 18.485978
B10: LY_healthy_y1_ag7 | C10: 17.716736 | D10: 17.737565 | E10: 17.758493 | F10: 17.77952 | G10: 17.799925 | H10: 17.820425 | I10: 17.841019 | J10: 17.861709 | K10: 17.882497 | L10: 17.902315 | M10: 17.922224 | N10: 17.942223 | O10: 17.962314 | P10: 17.982496 | Q10: 18.001943 | R10: 18.021478 | S10: 18.0411 | T10: 18.060811 | U10: 18.080612 | V10: 18.099527 | W10: 18.118529 | X10: 18.137617 | Y10: 18.156794 | Z10: 18.17606 | AA10: 18.193803 | AC10: LY_postTB_y1_ag7 | AD10: 17.519517 | AE10: 17.542054 | AF10: 17.564705 | AG10: 17.587473 | AH10: 17.60957 | AI10: 17.631778 | AJ10: 17.654097 | AK10: 17.676528 | AL10: 17.699073 | AM10: 17.720563 | AN10: 17.742158 | AO10: 17.763859 | AP10: 17.785667 | AQ10: 17.807583 | AR10: 17.828698 | AS10: 17.849916 | AT10: 17.871236 | AU10: 17.892661 | AV10: 17.914191 | AW10: 17.934734 | AX10: 17.955379 | AY10: 17.976125 | AZ10: 17.996975 | BA10: 18.017929 | BB10: 18.037214
B11: LY_healthy_y1_ag8 | C11: 17.127655 | D11: 17.151362 | E11: 17.175187 | F11: 17.199132 | G11: 17.222306 | H11: 17.245594 | I11: 17.268997 | J11: 17.292516 | K11: 17.316151 | L11: 17.338681 | M11: 17.36132 | N11: 17.384068 | O11: 17.406926 | P11: 17.429896 | Q11: 17.452056 | R11: 17.474322 | S11: 17.496695 | T11: 17.519174 | U11: 17.541763 | V11: 17.563452 | W11: 17.585247 | X11: 17.607148 | Y11: 17.629155 | Z11: 17.651271 | AA11: 17.671715 | AC11: LY_postTB_y1_ag8 | AD11: 16.898648 | AE11: 16.924193 | AF11: 16.949877 | AG11: 16.9757 | AH11: 17.000693 | AI11: 17.025819 | AJ11: 17.051079 | AK11: 17.076473 | AL11: 17.102004 | AM11: 17.126335 | AN11: 17.150792 | AO11: 17.175377 | AP11: 17.200091 | AQ11: 17.224936 | AR11: 17.248902 | AS11: 17.272992 | AT11: 17.297206 | AU11: 17.321547 | AV11: 17.346013 | AW11: 17.369481 | AX11: 17.393072 | AY11: 17.416787 | AZ11: 17.440626 | BA11: 17.464593 | BB11: 17.486732
B12: LY_healthy_y1_ag9 | C12: 16.417157 | D12: 16.444077 | E12: 16.471139 | F12: 16.498346 | G12: 16.52461 | H12: 16.551011 | I12: 16.57755 | J12: 16.604227 | K12: 16.631044 | L12: 16.656592 | M12: 16.68227 | N12: 16.708079 | O12: 16.73402 | P12: 16.760095 | Q12: 16.785265 | R12: 16.810561 | S12: 16.835986 | T12: 16.861539 | U12: 16.887223 | V12: 16.91202 | W12: 16.936943 | X12: 16.961995 | Y12: 16.987177 | Z12: 17.012488 | AA12: 17.035972 | AC12: LY_postTB_y1_ag9 | AD12: 16.152171 | AE12: 16.181059 | AF12: 16.210113 | AG12: 16.239335 | AH12: 16.267541 | AI12: 16.295906 | AJ12: 16.324431 | AK12: 16.353118 | AL12: 16.381967 | AM12: 16.409441 | AN12: 16.437067 | AO12: 16.464845 | AP12: 16.492778 | AQ12: 16.520866 | AR12: 16.547976 | AS12: 16.575233 | AT12: 16.60264 | AU12: 16.630197 | AV12: 16.657906 | AW12: 16.684631 | AX12: 16.711504 | AY12: 16.738527 | AZ12: 16.7657 | BA12: 16.793026 | BB12: 16.818363
B13: LY_healthy_y1_ag10 | C13: 15.575 | D13: 15.605263 | E13: 15.635694 | F13: 15.666295 | G13: 15.69579 | H13: 15.725446 | I13: 15.755264 | J13: 15.785245 | K13: 15.815392 | L13: 15.844114 | M13: 15.872989 | N13: 15.902019 | O13: 15.931206 | P13: 15.960551 | Q13: 15.988879 | R13: 16.017356 | S13: 16.045985 | T13: 16.074767 | U13: 16.103703 | V13: 16.131788 | W13: 16.160025 | X13: 16.188415 | Y13: 16.216959 | Z13: 16.245658 | AA13: 16.272384 | AC13: LY_postTB_y1_ag10 | AD13: 15.271065 | AE13: 15.3034 | AF13: 15.335929 | AG13: 15.368656 | AH13: 15.40019 | AI13: 15.431912 | AJ13: 15.463822 | AK13: 15.495922 | AL13: 15.528213 | AM13: 15.558964 | AN13: 15.589893 | AO13: 15.621002 | AP13: 15.652294 | AQ13: 15.683769 | AR13: 15.714147 | AS13: 15.744699 | AT13: 15.775427 | AU13: 15.806334 | AV13: 15.837419 | AW13: 15.867562 | AX13: 15.897881 | AY13: 15.928378 | AZ13: 15.959054 | BA13: 15.989911 | BB13: 16.018631
B14: LY_healthy_y1_ag11 | C14: 14.601758 | D14: 14.63505 | E14: 14.668536 | F14: 14.702217 | G14: 14.734655 | H14: 14.767278 | I14: 14.800088 | J14: 14.833087 | K14: 14.866277 | L14: 14.897935 | M14: 14.929771 | N14: 14.961786 | O14: 14.993983 | P14: 15.026363 | Q14: 15.057634 | R14: 15.08908 | S14: 15.120702 | T14: 15.1525 | U14: 15.184478 | V14: 15.21568 | W14: 15.247059 | X14: 15.278616 | Y14: 15.310354 | Z14: 15.342273 | AA14: 15.372107 | AC14: LY_postTB_y1_ag11 | AD14: 14.258704 | AE14: 14.294101 | AF14: 14.329722 | AG14: 14.365569 | AH14: 14.400077 | AI14: 14.4348 | AJ14: 14.469739 | AK14: 14.504897 | AL14: 14.540275 | AM14: 14.574002 | AN14: 14.607934 | AO14: 14.642075 | AP14: 14.676425 | AQ14: 14.710987 | AR14: 14.744358 | AS14: 14.777931 | AT14: 14.811707 | AU14: 14.845688 | AV14: 14.879877 | AW14: 14.913206 | AX14: 14.94674 | AY14: 14.98048 | AZ14: 15.014429 | BA14: 15.048589 | BB14: 15.080502
B15: LY_healthy_y1_ag12 | C15: 13.485549 | D15: 13.52126 | E15: 13.557186 | F15: 13.593329 | G15: 13.628164 | H15: 13.663205 | I15: 13.698456 | J15: 13.733918 | K15: 13.769592 | L15: 13.803684 | M15: 13.837976 | N15: 13.872469 | O15: 13.907166 | P15: 13.942067 | Q15: 13.975816 | R15: 14.009761 | S15: 14.043903 | T15: 14.078245 | U15: 14.112788 | V15: 14.146684 | W15: 14.18078 | X15: 14.21508 | Y15: 14.249583 | Z15: 14.284293 | AA15: 14.316854 | AC15: LY_postTB_y1_ag12 | AD15: 13.104665 | AE15: 13.142429 | AF15: 13.180441 | AG15: 13.218703 | AH15: 13.255558 | AI15: 13.292651 | AJ15: 13.329985 | AK15: 13.367562 | AL15: 13.405385 | AM15: 13.441505 | AN15: 13.477856 | AO15: 13.514439 | AP15: 13.551256 | AQ15: 13.58831 | AR15: 13.624128 | AS15: 13.660172 | AT15: 13.696444 | AU15: 13.732946 | AV15: 13.769681 | AW15: 13.805694 | AX15: 13.841938 | AY15: 13.878416 | AZ15: 13.915131 | BA15: 13.952084 | BB15: 13.986731
... B19: LY_healthy_y1_ag16 | C19: 7.2838501 | D19: 7.3083636 | E19: 7.3330021 | F19: 7.3577664 | G19: 7.3827571 | H19: 7.4078791 | I19: 7.4331334 | J19: 7.4585207 | K19: 7.484042 | L19: 7.5095963 | M19: 7.5352885 | N19: 7.5611197 | O19: 7.5870908 | P19: 7.6132028 | Q19: 7.6392851 | R19: 7.6655113 | S19: 7.6918823 | T19: 7.7183992 | U19: 7.7450629 | V19: 7.7725899 | W19: 7.8002782 | X19: 7.8281289 | Y19: 7.8561434 | Z19: 7.8843229 | AA19: 7.9116871 | AC19: LY_postTB_y1_ag16 | AD19: 6.8460195 | AE19: 6.8711267 | AF19: 6.8963747 | AG19: 6.9217646 | AH19: 6.9473582 | AI19: 6.9730997 | AJ19: 6.9989901 | AK19: 7.0250304 | AL19: 7.0512217 | AM19: 7.0774144 | AN19: 7.1037625 | AO19: 7.1302669 | AP19: 7.156929 | AQ19: 7.1837498 | AR19: 7.2105166 | AS19: 7.2374453 | AT19: 7.2645372 | AU19: 7.2917934 | AV19: 7.3192154 | AW19: 7.3474898 | AX19: 7.3759458 | AY19: 7.4045849 | AZ19: 7.4334086 | BA19: 7.4624184 | BB19: 7.4905704
B20: LY_healthy_y2_ag1 | C20: =D4*(1+disc)^-1 -> 18.729772 | AC20: LY_postTB_y2_ag1 | AD20: =AE4*(1+disc)^-1 -> 18.662262
B21: LY_healthy_y2_ag2 | C21: =D5*(1+disc)^-1 -> 18.547578 | AC21: LY_postTB_y2_ag2 | AD21: =AE5*(1+disc)^-1 -> 18.46646
B22: LY_healthy_y2_ag3 | C22: =D6*(1+disc)^-1 -> 18.300094 | AC22: LY_postTB_y2_ag3 | AD22: =AE6*(1+disc)^-1 -> 18.199551
B23: LY_healthy_y2_ag4 | C23: =D7*(1+disc)^-1 -> 18.013981 | AC23: LY_postTB_y2_ag4 | AD23: =AE7*(1+disc)^-1 -> 17.892565
B24: LY_healthy_y2_ag5 | C24: =D8*(1+disc)^-1 -> 17.709592 | AC24: LY_postTB_y2_ag5 | AD24: =AE8*(1+disc)^-1 -> 17.569479
B25: LY_healthy_y2_ag6 | C25: =D9*(1+disc)^-1 -> 17.349725 | AC25: LY_postTB_y2_ag6 | AD25: =AE9*(1+disc)^-1 -> 17.189336
B26: LY_healthy_y2_ag7 | C26: =D10*(1+disc)^-1 -> 16.892919 | AC26: LY_postTB_y2_ag7 | AD26: =AE10*(1+disc)^-1 -> 16.706718
B27: LY_healthy_y2_ag8 | C27: =D11*(1+disc)^-1 -> 16.33463 | AC27: LY_postTB_y2_ag8 | AD27: =AE11*(1+disc)^-1 -> 16.118279
B28: LY_healthy_y2_ag9 | C28: =D12*(1+disc)^-1 -> 15.661026 | AC28: LY_postTB_y2_ag9 | AD28: =AE12*(1+disc)^-1 -> 15.410533
B29: LY_healthy_y2_ag10 | C29: =D13*(1+disc)^-1 -> 14.862155 | AC29: LY_postTB_y2_ag10 | AD29: =AE13*(1+disc)^-1 -> 14.574666
B30: LY_healthy_y2_ag11 | C30: =D14*(1+disc)^-1 -> 13.938143 | AC30: LY_postTB_y2_ag11 | AD30: =AE14*(1+disc)^-1 -> 13.61343
B31: LY_healthy_y2_ag12 | C31: =D15*(1+disc)^-1 -> 12.87739 | AC31: LY_postTB_y2_ag12 | AD31: =AE15*(1+disc)^-1 -> 12.516599
... B35: LY_healthy_y2_ag16 | C35: =D19*(1+disc)^-1 -> 6.9603463 | AC35: LY_postTB_y2_ag16 | AD35: =AE19*(1+disc)^-1 -> 6.5439302
B36: LY_healthy_y3_ag1 | C36: =E4*(1+disc)^-2 -> 17.84609 | AC36: LY_postTB_y3_ag1 | AD36: =AF4*(1+disc)^-2 -> 17.782645
B37: LY_healthy_y3_ag2 | C37: =E5*(1+disc)^-2 -> 17.673879 | AC37: LY_postTB_y3_ag2 | AD37: =AF5*(1+disc)^-2 -> 17.59758
B38: LY_healthy_y3_ag3 | C38: =E6*(1+disc)^-2 -> 17.440315 | AC38: LY_postTB_y3_ag3 | AD38: =AF6*(1+disc)^-2 -> 17.345716
B39: LY_healthy_y3_ag4 | C39: =E7*(1+disc)^-2 -> 17.169908 | AC39: LY_postTB_y3_ag4 | AD39: =AF7*(1+disc)^-2 -> 17.055604
B40: LY_healthy_y3_ag5 | C40: =E8*(1+disc)^-2 -> 16.881483 | AC40: LY_postTB_y3_ag5 | AD40: =AF8*(1+disc)^-2 -> 16.749441
B41: LY_healthy_y3_ag6 | C41: =E9*(1+disc)^-2 -> 16.54031 | AC41: LY_postTB_y3_ag6 | AD41: =AF9*(1+disc)^-2 -> 16.389015
B42: LY_healthy_y3_ag7 | C42: =E10*(1+disc)^-2 -> 16.107477 | AC42: LY_postTB_y3_ag7 | AD42: =AF10*(1+disc)^-2 -> 15.931705
B43: LY_healthy_y3_ag8 | C43: =E11*(1+disc)^-2 -> 15.578401 | AC43: LY_postTB_y3_ag8 | AD43: =AF11*(1+disc)^-2 -> 15.374038
B44: LY_healthy_y3_ag9 | C44: =E12*(1+disc)^-2 -> 14.939809 | AC44: LY_postTB_y3_ag9 | AD44: =AF12*(1+disc)^-2 -> 14.703051
B45: LY_healthy_y3_ag10 | C45: =E13*(1+disc)^-2 -> 14.182036 | AC45: LY_postTB_y3_ag10 | AD45: =AF13*(1+disc)^-2 -> 13.91014
B46: LY_healthy_y3_ag11 | C46: =E14*(1+disc)^-2 -> 13.304794 | AC46: LY_postTB_y3_ag11 | AD46: =AF14*(1+disc)^-2 -> 12.99748
...

Sheet LE_IND
A1: LIFE EXPECTANCY | C1: INDIA | AC1: Mortality RR = 1.14
B2: Healthy life expectancy (discounted) | C2: y1 | D2: y2 | E2: y3 | F2: y4 | G2: y5 | H2: y6 | I2: y7 | J2: y8 | K2: y9 | L2: y10 | M2: y11 | N2: y12 | O2: y13 | P2: y14 | Q2: y15 | R2: y16 | S2: y17 | T2: y18 | U2: y19 | V2: y20 | W2: y21 | X2: y22 | Y2: y23 | Z2: y24 | AA2: y25 | AC2: Post-TB life expectancy (discounted) | AD2: y1 | AE2: y2 | AF2: y3 | AG2: y4 | AH2: y5 | AI2: y6 | AJ2: y7 | AK2: y8 | AL2: y9 | AM2: y10 | AN2: y11 | AO2: y12 | AP2: y13 | AQ2: y14 | AR2: y15 | AS2: y16 | AT2: y17 | AU2: y18 | AV2: y19 | AW2: y20 | AX2: y21 | AY2: y22 | AZ2: y23 | BA2: y24 | BB2: y25
C3: 2025 | D3: 2026 | E3: 2027 | F3: 2028 | G3: 2029 | H3: 2030 | I3: 2031 | J3: 2032 | K3: 2033 | L3: 2034 | M3: 2035 | N3: 2036 | O3: 2037 | P3: 2038 | Q3: 2039 | R3: 2040 | S3: 2041 | T3: 2042 | U3: 2043 | V3: 2044 | W3: 2045 | X3: 2046 | Y3: 2047 | Z3: 2048 | AA3: 2049 | AD3: 2025 | AE3: 2026 | AF3: 2027 | AG3: 2028 | AH3: 2029 | AI3: 2030 | AJ3: 2031 | AK3: 2032 | AL3: 2033 | AM3: 2034 | AN3: 2035 | AO3: 2036 | AP3: 2037 | AQ3: 2038 | AR3: 2039 | AS3: 2040 | AT3: 2041 | AU3: 2042 | AV3: 2043 | AW3: 2044 | AX3: 2045 | AY3: 2046 | AZ3: 2047 | BA3: 2048 | BB3: 2049
B4: LY_healthy_y1_ag1 | C4: 19.450539 | D4: 19.461962 | E4: 19.473411 | F4: 19.484886 | G4: 19.494302 | H4: 19.50374 | I4: 19.513199 | J4: 19.52268 | K4: 19.532183 | L4: 19.540354 | M4: 19.548545 | N4: 19.556755 | O4: 19.564984 | P4: 19.573234 | Q4: 19.580612 | R4: 19.588009 | S4: 19.595424 | T4: 19.602859 | U4: 19.610313 | V4: 19.617172 | W4: 19.624049 | X4: 19.630945 | Y4: 19.63786 | Z4: 19.644794 | AA4: 19.651228 | AC4: LY_postTB_y1_ag1 | AD4: 19.363234 | AE4: 19.375913 | AF4: 19.388623 | AG4: 19.401363 | AH4: 19.411781 | AI4: 19.422225 | AJ4: 19.432694 | AK4: 19.443189 | AL4: 19.453709 | AM4: 19.462729 | AN4: 19.471771 | AO4: 19.480836 | AP4: 19.489923 | AQ4: 19.499034 | AR4: 19.507158 | AS4: 19.515305 | AT4: 19.523472 | AU4: 19.531662 | AV4: 19.539874 | AW4: 19.547413 | AX4: 19.554973 | AY4: 19.562555 | AZ4: 19.570158 | BA4: 19.577783 | BB4: 19.584847
B5: LY_healthy_y1_ag2 | C5: 19.288409 | D5: 19.298937 | E5: 19.309493 | F5: 19.320078 | G5: 19.328984 | H5: 19.337914 | I5: 19.346869 | J5: 19.355849 | K5: 19.364855 | L5: 19.372777 | M5: 19.380721 | N5: 19.388689 | O5: 19.396679 | P5: 19.404693 | Q5: 19.412033 | R5: 19.419396 | S5: 19.426781 | T5: 19.434189 | U5: 19.44162 | V5: 19.448617 | W5: 19.455636 | X5: 19.462677 | Y5: 19.469742 | Z5: 19.476829 | AA5: 19.483539 | AC5: LY_postTB_y1_ag2 | AD5: 19.194228 | AE5: 19.20582 | AF5: 19.217445 | AG5: 19.229104 | AH5: 19.238875 | AI5: 19.248674 | AJ5: 19.258502 | AK5: 19.26836 | AL5: 19.278246 | AM5: 19.286916 | AN5: 19.295612 | AO5: 19.304334 | AP5: 19.313083 | AQ5: 19.321859 | AR5: 19.329874 | AS5: 19.337915 | AT5: 19.345981 | AU5: 19.354074 | AV5: 19.362193 | AW5: 19.369821 | AX5: 19.377476 | AY5: 19.385156 | AZ5: 19.392862 | BA5: 19.400595 | BB5: 19.407906
B6: LY_healthy_y1_ag3 | C6: 19.012867 | D6: 19.024661 | E6: 19.036489 | F6: 19.048352 | G6: 19.058461 | H6: 19.068599 | I6: 19.078768 | J6: 19.088968 | K6: 19.099198 | L6: 19.108293 | M6: 19.117416 | N6: 19.126567 | O6: 19.135747 | P6: 19.144955 | Q6: 19.153473 | R6: 19.162019 | S6: 19.170593 | T6: 19.179196 | U6: 19.187827 | V6: 19.196023 | W6: 19.204248 | X6: 19.212501 | Y6: 19.220783 | Z6: 19.229093 | AA6: 19.237017 | AC6: LY_postTB_y1_ag3 | AD6: 18.900595 | AE6: 18.913531 | AF6: 18.926508 | AG6: 18.939525 | AH6: 18.950571 | AI6: 18.961653 | AJ6: 18.972769 | AK6: 18.983922 | AL6: 18.99511 | AM6: 19.005025 | AN6: 19.014972 | AO6: 19.024952 | AP6: 19.034965 | AQ6: 19.045011 | AR6: 19.054277 | AS6: 19.063575 | AT6: 19.072906 | AU6: 19.082269 | AV6: 19.091664 | AW6: 19.10057 | AX6: 19.109508 | AY6: 19.118479 | AZ6: 19.127482 | BA6: 19.136518 | BB6: 19.145125
B7: LY_healthy_y1_ag4 | C7: 18.666452 | D7: 18.679931 | E7: 18.693451 | F7: 18.707014 | G7: 18.718711 | H7: 18.730444 | I7: 18.742216 | J7: 18.754025 | K7: 18.765872 | L7: 18.776505 | M7: 18.787172 | N7: 18.797875 | O7: 18.808614 | P7: 18.819388 | Q7: 18.829439 | R7: 18.839525 | S7: 18.849646 | T7: 18.859803 | U7: 18.869995 | V7: 18.879738 | W7: 18.889517 | X7: 18.899331 | Y7: 18.90918 | Z7: 18.919066 | AA7: 18.928539 | AC7: LY_postTB_y1_ag4 | AD7: 18.531703 | AE7: 18.546436 | AF7: 18.561217 | AG7: 18.576048 | AH7: 18.588786 | AI7: 18.601566 | AJ7: 18.614391 | AK7: 18.627258 | AL7: 18.64017 | AM7: 18.651723 | AN7: 18.663316 | AO7: 18.674949 | AP7: 18.686624 | AQ7: 18.698339 | AR7: 18.709238 | AS7: 18.720177 | AT7: 18.731156 | AU7: 18.742176 | AV7: 18.753236 | AW7: 18.763791 | AX7: 18.774386 | AY7: 18.785021 | AZ7: 18.795698 | BA7: 18.806416 | BB7: 18.816676
B8: LY_healthy_y1_ag5 | C8: 18.257283 | D8: 18.27236 | E8: 18.287489 | F8: 18.302668 | G8: 18.315971 | H8: 18.32932 | I8: 18.342714 | J8: 18.356155 | K8: 18.369643 | L8: 18.381899 | M8: 18.394198 | N8: 18.406541 | O8: 18.418927 | P8: 18.431358 | Q8: 18.443078 | R8: 18.454842 | S8: 18.466649 | T8: 18.478501 | U8: 18.490397 | V8: 18.50185 | W8: 18.513346 | X8: 18.524887 | Y8: 18.536473 | Z8: 18.548104 | AA8: 18.559302 | AC8: LY_postTB_y1_ag5 | AD8: 18.098061 | AE8: 18.114469 | AF8: 18.130935 | AG8: 18.147461 | AH8: 18.161886 | AI8: 18.176364 | AJ8: 18.190894 | AK8: 18.205478 | AL8: 18.220116 | AM8: 18.233379 | AN8: 18.246691 | AO8: 18.260053 | AP8: 18.273465 | AQ8: 18.286928 | AR8: 18.299589 | AS8: 18.312299 | AT8: 18.325059 | AU8: 18.337869 | AV8: 18.350731 | AW8: 18.363093 | AX8: 18.375506 | AY8: 18.387969 | AZ8: 18.400483 | BA8: 18.413049 | BB8: 18.425137
B9: LY_healthy_y1_ag6 | C9: 17.763548 | D9: 17.780275 | E9: 17.797062 | F9: 17.813909 | G9: 17.82895 | H9: 17.844046 | I9: 17.859198 | J9: 17.874406 | K9: 17.889671 | L9: 17.903735 | M9: 17.917851 | N9: 17.932021 | O9: 17.946245 | P9: 17.960523 | Q9: 17.974144 | R9: 17.987818 | S9: 18.001547 | T9: 18.015331 | U9: 18.029169 | V9: 18.042587 | W9: 18.056059 | X9: 18.069587 | Y9: 18.08317 | Z9: 18.09681 | AA9: 18.109993 | AC9: LY_postTB_y1_ag6 | AD9: 17.576597 | AE9: 17.594708 | AF9: 17.612888 | AG9: 17.631139 | AH9: 17.64737 | AI9: 17.663665 | AJ9: 17.680024 | AK9: 17.696447 | AL9: 17.712936 | AM9: 17.728087 | AN9: 17.743298 | AO9: 17.758571 | AP9: 17.773905 | AQ9: 17.789301 | AR9: 17.803954 | AS9: 17.818669 | AT9: 17.833446 | AU9: 17.848285 | AV9: 17.863187 | AW9: 17.877615 | AX9: 17.892106 | AY9: 17.906659 | AZ9: 17.921276 | BA9: 17.935956 | BB9: 17.950137
B10: LY_healthy_y1_ag7 | C10: 17.154855 | D10: 17.173518 | E10: 17.192252 | F10: 17.211059 | G10: 17.228153 | H10: 17.245314 | I10: 17.262542 | J10: 17.279839 | K10: 17.297205 | L10: 17.313403 | M10: 17.329666 | N10: 17.345995 | O10: 17.36239 | P10: 17.378851 | Q10: 17.39473 | R10: 17.410675 | S10: 17.426688 | T10: 17.442767 | U10: 17.458915 | V10: 17.474679 | W10: 17.49051 | X10: 17.50641 | Y10: 17.522378 | Z10: 17.538417 | AA10: 17.553969 | AC10: LY_postTB_y1_ag7 | AD10: 16.934938 | AE10: 16.955042 | AF10: 16.975229 | AG10: 16.995498 | AH10: 17.013856 | AI10: 17.032291 | AJ10: 17.050804 | AK10: 17.069394 | AL10: 17.088063 | AM10: 17.105436 | AN10: 17.122884 | AO10: 17.140406 | AP10: 17.158003 | AQ10: 17.175676 | AR10: 17.19269 | AS10: 17.209779 | AT10: 17.226944 | AU10: 17.244186 | AV10: 17.261506 | AW10: 17.278393 | AX10: 17.295357 | AY10: 17.312399 | AZ10: 17.329519 | BA10: 17.346718 | BB10: 17.363388
B11: LY_healthy_y1_ag8 | C11: 16.421132 | D11: 16.441803 | E11: 16.462559 | F11: 16.4834 | G11: 16.5027 | H11: 16.522081 | I11: 16.541544 | J11: 16.561088 | K11: 16.580715 | L11: 16.599237 | M11: 16.617837 | N11: 16.636517 | O11: 16.655277 | P11: 16.674118 | Q11: 16.692471 | R11: 16.710906 | S11: 16.729422 | T11: 16.748021 | U11: 16.766703 | V11: 16.785059 | W11: 16.803498 | X11: 16.822021 | Y11: 16.840629 | Z11: 16.859323 | AA11: 16.877515 | AC11: LY_postTB_y1_ag8 | AD11: 16.164056 | AE11: 16.186198 | AF11: 16.208436 | AG11: 16.230773 | AH11: 16.251393 | AI11: 16.272105 | AJ11: 16.292909 | AK11: 16.313807 | AL11: 16.334799 | AM11: 16.354568 | AN11: 16.374426 | AO11: 16.394375 | AP11: 16.414414 | AQ11: 16.434546 | AR11: 16.454122 | AS11: 16.473791 | AT11: 16.493552 | AU11: 16.513407 | AV11: 16.533357 | AW11: 16.552938 | AX11: 16.572614 | AY11: 16.592386 | AZ11: 16.612253 | BA11: 16.632218 | BB11: 16.651638
B12: LY_healthy_y1_ag9 | C12: 15.546254 | D12: 15.568924 | E12: 15.591693 | F12: 15.614562 | G12: 15.636151 | H12: 15.657835 | I12: 15.679617 | J12: 15.701496 | K12: 15.723473 | L12: 15.744452 | M12: 15.765527 | N12: 15.786697 | O12: 15.807963 | P12: 15.829327 | Q12: 15.85031 | R12: 15.871391 | S12: 15.892572 | T12: 15.913853 | U12: 15.935234 | V12: 15.95634 | W12: 15.977548 | X12: 15.998858 | Y12: 16.020271 | Z12: 16.041788 | AA12: 16.062794 | AC12: LY_postTB_y1_ag9 | AD12: 15.248489 | AE12: 15.272621 | AF12: 15.296866 | AG12: 15.321224 | AH12: 15.344158 | AI12: 15.367199 | AJ12: 15.390351 | AK12: 15.413613 | AL12: 15.436987 | AM12: 15.45926 | AN12: 15.48164 | AO12: 15.504129 | AP12: 15.526727 | AQ12: 15.549434 | AR12: 15.571704 | AS12: 15.594085 | AT12: 15.616577 | AU12: 15.639183 | AV12: 15.661903 | AW12: 15.684311 | AX12: 15.706833 | AY12: 15.729471 | AZ12: 15.752226 | BA12: 15.775098 | BB12: 15.79742
B13: LY_healthy_y1_ag10 | C13: 14.511402 | D13: 14.536137 | E13: 14.560985 | F13: 14.585948 | G13: 14.609932 | H13: 14.634028 | I13: 14.658238 | J13: 14.682563 | K13: 14.707002 | L13: 14.730585 | M13: 14.75428 | N13: 14.778089 | O13: 14.802011 | P13: 14.826049 | Q13: 14.84983 | R13: 14.873729 | S13: 14.897746 | T13: 14.921883 | U13: 14.946141 | V13: 14.970143 | W13: 14.994268 | X13: 15.018515 | Y13: 15.042886 | Z13: 15.067383 | AA13: 15.091315 | AC13: LY_postTB_y1_ag10 | AD13: 14.17006 | AE13: 14.196221 | AF13: 14.22251 | AG13: 14.248929 | AH13: 14.274257 | AI13: 14.299711 | AJ13: 14.325293 | AK13: 14.351004 | AL13: 14.376846 | AM13: 14.401744 | AN13: 14.42677 | AO13: 14.451923 | AP13: 14.477205 | AQ13: 14.502617 | AR13: 14.527723 | AS13: 14.552961 | AT13: 14.578333 | AU13: 14.60384 | AV13: 14.629483 | AW13: 14.654834 | AX13: 14.680322 | AY13: 14.705949 | AZ13: 14.731715 | BA13: 14.757622 | BB13: 14.782924
B14: LY_healthy_y1_ag11 | C14: 13.33182 | D14: 13.358183 | E14: 13.384674 | F14: 13.411292 | G14: 13.43731 | H14: 13.463456 | I14: 13.489732 | J14: 13.516138 | K14: 13.542675 | L14: 13.568537 | M14: 13.594527 | N14: 13.620649 | O14: 13.646902 | P14: 13.673289 | Q14: 13.69958 | R14: 13.726009 | S14: 13.752575 | T14: 13.779281 | U14: 13.806127 | V14: 13.832758 | W14: 13.859532 | X14: 13.886449 | Y14: 13.913512 | Z14: 13.94072 | AA14: 13.967294 | AC14: LY_postTB_y1_ag11 | AD14: 12.948633 | AE14: 12.976318 | AF14: 13.004147 | AG14: 13.032119 | AH14: 13.059412 | AI14: 13.08685 | AJ14: 13.114433 | AK14: 13.142162 | AL14: 13.170039 | AM14: 13.197171 | AN14: 13.224449 | AO14: 13.251874 | AP14: 13.279447 | AQ14: 13.30717 | AR14: 13.334758 | AS14: 13.362499 | AT14: 13.390396 | AU14: 13.418448 | AV14: 13.446659 | AW14: 13.474617 | AX14: 13.502734 | AY14: 13.531013 | AZ14: 13.559454 | BA14: 13.588059 | BB14: 13.615984
B15: LY_healthy_y1_ag12 | C15: 12.032752 | D15: 12.059688 | E15: 12.08676 | F15: 12.113969 | G15: 12.141063 | H15: 12.168298 | I15: 12.195673 | J15: 12.223192 | K15: 12.250853 | L15: 12.278116 | M15: 12.305522 | N15: 12.333073 | O15: 12.36077 | P15: 12.388614 | Q15: 12.416568 | R15: 12.444674 | S15: 12.472935 | T15: 12.501352 | U15: 12.529926 | V15: 12.558386 | W15: 12.587007 | X15: 12.61579 | Y15: 12.644736 | Z15: 12.673848 | AA15: 12.702309 | AC15: LY_postTB_y1_ag12 | AD15: 11.614808 | AE15: 11.642851 | AF15: 11.671045 | AG15: 11.699392 | AH15: 11.727586 | AI15: 11.755937 | AJ15: 11.784446 | AK15: 11.813113 | AL15: 11.841941 | AM15: 11.870325 | AN15: 11.89887 | AO15: 11.927576 | AP15: 11.956446 | AQ15: 11.98548 | AR15: 12.014592 | AS15: 12.043876 | AT15: 12.073332 | AU15: 12.102962 | AV15: 12.132768 | AW15: 12.162425 | AX15: 12.192261 | AY15: 12.222278 | AZ15: 12.252476 | BA15: 12.282859 | BB15: 12.312546
... B19: LY_healthy_y1_ag16 | C19: 5.5729237 | D19: 5.5889556 | E19: 5.6050625 | F19: 5.6212448 | G19: 5.6378734 | H19: 5.6545819 | I19: 5.6713707 | J19: 5.6882405 | K19: 5.7051916 | L19: 5.7225143 | M19: 5.7399217 | N19: 5.7574144 | O19: 5.7749929 | P19: 5.7926577 | Q19: 5.8114494 | R19: 5.8303401 | S19: 5.8493305 | T19: 5.8684213 | U19: 5.8876131 | V19: 5.9077265 | W19: 5.9279539 | X19: 5.9482962 | Y19: 5.9687542 | Z19: 5.9893286 | AA19: 6.0101953 | AC19: LY_postTB_y1_ag16 | AD19: 5.1528629 | AE19: 5.1687274 | AF19: 5.1846722 | AG19: 5.2006978 | AH19: 5.217169 | AI19: 5.2337259 | AJ19: 5.2503689 | AK19: 5.2670986 | AL19: 5.2839157 | AM19: 5.3011149 | AN19: 5.3184051 | AO19: 5.3357871 | AP19: 5.3532614 | AQ19: 5.3708287 | AR19: 5.3895047 | AS19: 5.4082874 | AT19: 5.4271774 | AU19: 5.4461755 | AV19: 5.4652826 | AW19: 5.4852731 | AX19: 5.5053862 | AY19: 5.5256227 | AZ19: 5.5459837 | BA19: 5.5664702 | BB19: 5.5872159
B20: LY_healthy_y2_ag1 | C20: =D4*(1+disc)^-1 -> 18.535202 | AC20: LY_postTB_y2_ag1 | AD20: =AE4*(1+disc)^-1 -> 18.453251
B21: LY_healthy_y2_ag2 | C21: =D5*(1+disc)^-1 -> 18.37994 | AC21: LY_postTB_y2_ag2 | AD21: =AE5*(1+disc)^-1 -> 18.291257
B22: LY_healthy_y2_ag3 | C22: =D6*(1+disc)^-1 -> 18.118725 | AC22: LY_postTB_y2_ag3 | AD22: =AE6*(1+disc)^-1 -> 18.012887
B23: LY_healthy_y2_ag4 | C23: =D7*(1+disc)^-1 -> 17.79041 | AC23: LY_postTB_y2_ag4 | AD23: =AE7*(1+disc)^-1 -> 17.663272
B24: LY_healthy_y2_ag5 | C24: =D8*(1+disc)^-1 -> 17.402248 | AC24: LY_postTB_y2_ag5 | AD24: =AE8*(1+disc)^-1 -> 17.251875
B25: LY_healthy_y2_ag6 | C25: =D9*(1+disc)^-1 -> 16.933595 | AC25: LY_postTB_y2_ag6 | AD25: =AE9*(1+disc)^-1 -> 16.756865
B26: LY_healthy_y2_ag7 | C26: =D10*(1+disc)^-1 -> 16.355731 | AC26: LY_postTB_y2_ag7 | AD26: =AE10*(1+disc)^-1 -> 16.147659
B27: LY_healthy_y2_ag8 | C27: =D11*(1+disc)^-1 -> 15.65886 | AC27: LY_postTB_y2_ag8 | AD27: =AE11*(1+disc)^-1 -> 15.415426
B28: LY_healthy_y2_ag9 | C28: =D12*(1+disc)^-1 -> 14.827547 | AC28: LY_postTB_y2_ag9 | AD28: =AE12*(1+disc)^-1 -> 14.545354
B29: LY_healthy_y2_ag10 | C29: =D13*(1+disc)^-1 -> 13.84394 | AC29: LY_postTB_y2_ag10 | AD29: =AE13*(1+disc)^-1 -> 13.52021
B30: LY_healthy_y2_ag11 | C30: =D14*(1+disc)^-1 -> 12.722079 | AC30: LY_postTB_y2_ag11 | AD30: =AE14*(1+disc)^-1 -> 12.358399
B31: LY_healthy_y2_ag12 | C31: =D15*(1+disc)^-1 -> 11.485417 | AC31: LY_postTB_y2_ag12 | AD31: =AE15*(1+disc)^-1 -> 11.088429
... B35: LY_healthy_y2_ag16 | C35: =D19*(1+disc)^-1 -> 5.3228148 | AC35: LY_postTB_y2_ag16 | AD35: =AE19*(1+disc)^-1 -> 4.9225976
B36: LY_healthy_y3_ag1 | C36: =E4*(1+disc)^-2 -> 17.662958 | AC36: LY_postTB_y3_ag1 | AD36: =AF4*(1+disc)^-2 -> 17.586052
B37: LY_healthy_y3_ag2 | C37: =E5*(1+disc)^-2 -> 17.51428 | AC37: LY_postTB_y3_ag2 | AD37: =AF5*(1+disc)^-2 -> 17.430789
B38: LY_healthy_y3_ag3 | C38: =E6*(1+disc)^-2 -> 17.266657 | AC38: LY_postTB_y3_ag3 | AD38: =AF6*(1+disc)^-2 -> 17.166901
B39: LY_healthy_y3_ag4 | C39: =E7*(1+disc)^-2 -> 16.955511 | AC39: LY_postTB_y3_ag4 | AD39: =AF7*(1+disc)^-2 -> 16.835571
B40: LY_healthy_y3_ag5 | C40: =E8*(1+disc)^-2 -> 16.587291 | AC40: LY_postTB_y3_ag5 | AD40: =AF8*(1+disc)^-2 -> 16.445293
B41: LY_healthy_y3_ag6 | C41: =E9*(1+disc)^-2 -> 16.142459 | AC41: LY_postTB_y3_ag6 | AD41: =AF9*(1+disc)^-2 -> 15.975409
B42: LY_healthy_y3_ag7 | C42: =E10*(1+disc)^-2 -> 15.59388 | AC42: LY_postTB_y3_ag7 | AD42: =AF10*(1+disc)^-2 -> 15.397033
B43: LY_healthy_y3_ag8 | C43: =E11*(1+disc)^-2 -> 14.932026 | AC43: LY_postTB_y3_ag8 | AD43: =AF11*(1+disc)^-2 -> 14.70153
B44: LY_healthy_y3_ag9 | C44: =E12*(1+disc)^-2 -> 14.142126 | AC44: LY_postTB_y3_ag9 | AD44: =AF12*(1+disc)^-2 -> 13.874709
B45: LY_healthy_y3_ag10 | C45: =E13*(1+disc)^-2 -> 13.207243 | AC45: LY_postTB_y3_ag10 | AD45: =AF13*(1+disc)^-2 -> 12.900236
B46: LY_healthy_y3_ag11 | C46: =E14*(1+disc)^-2 -> 12.140294 | AC46: LY_postTB_y3_ag11 | AD46: =AF14*(1+disc)^-2 -> 11.795144
...

Sheet LE_ZAF
A1: LIFE EXPECTANCY | C1: SOUTH AFRICA | AC1: Mortality RR = 1.14
B2: Healthy life expectancy (discounted) | C2: y1 | D2: y2 | E2: y3 | F2: y4 | G2: y5 | H2: y6 | I2: y7 | J2: y8 | K2: y9 | L2: y10 | M2: y11 | N2: y12 | O2: y13 | P2: y14 | Q2: y15 | R2: y16 | S2: y17 | T2: y18 | U2: y19 | V2: y20 | W2: y21 | X2: y22 | Y2: y23 | Z2: y24 | AA2: y25 | AC2: Post-TB life expectancy (discounted) | AD2: y1 | AE2: y2 | AF2: y3 | AG2: y4 | AH2: y5 | AI2: y6 | AJ2: y7 | AK2: y8 | AL2: y9 | AM2: y10 | AN2: y11 | AO2: y12 | AP2: y13 | AQ2: y14 | AR2: y15 | AS2: y16 | AT2: y17 | AU2: y18 | AV2: y19 | AW2: y20 | AX2: y21 | AY2: y22 | AZ2: y23 | BA2: y24 | BB2: y25
C3: 2025 | D3: 2026 | E3: 2027 | F3: 2028 | G3: 2029 | H3: 2030 | I3: 2031 | J3: 2032 | K3: 2033 | L3: 2034 | M3: 2035 | N3: 2036 | O3: 2037 | P3: 2038 | Q3: 2039 | R3: 2040 | S3: 2041 | T3: 2042 | U3: 2043 | V3: 2044 | W3: 2045 | X3: 2046 | Y3: 2047 | Z3: 2048 | AA3: 2049 | AD3: 2025 | AE3: 2026 | AF3: 2027 | AG3: 2028 | AH3: 2029 | AI3: 2030 | AJ3: 2031 | AK3: 2032 | AL3: 2033 | AM3: 2034 | AN3: 2035 | AO3: 2036 | AP3: 2037 | AQ3: 2038 | AR3: 2039 | AS3: 2040 | AT3: 2041 | AU3: 2042 | AV3: 2043 | AW3: 2044 | AX3: 2045 | AY3: 2046 | AZ3: 2047 | BA3: 2048 | BB3: 2049
B4: LY_healthy_y1_ag1 | C4: 19.060729 | D4: 19.078211 | E4: 19.095756 | F4: 19.113363 | G4: 19.128168 | H4: 19.143019 | I4: 19.157916 | J4: 19.172858 | K4: 19.187846 | L4: 19.200761 | M4: 19.213711 | N4: 19.226698 | O4: 19.23972 | P4: 19.252778 | Q4: 19.264359 | R4: 19.27597 | S4: 19.28761 | T4: 19.29928 | U4: 19.310981 | V4: 19.321272 | W4: 19.331589 | X4: 19.341931 | Y4: 19.352299 | Z4: 19.362693 | AA4: 19.37177 | AC4: LY_postTB_y1_ag1 | AD4: 18.935661 | AE4: 18.954963 | AF4: 18.974341 | AG4: 18.993794 | AH4: 19.010144 | AI4: 19.026548 | AJ4: 19.043008 | AK4: 19.059524 | AL4: 19.076096 | AM4: 19.090365 | AN4: 19.104678 | AO4: 19.119034 | AP4: 19.133433 | AQ4: 19.147876 | AR4: 19.160676 | AS4: 19.173512 | AT4: 19.186384 | AU4: 19.199291 | AV4: 19.212235 | AW4: 19.223598 | AX4: 19.234992 | AY4: 19.246416 | AZ4: 19.257872 | BA4: 19.269358 | BB4: 19.27937
B5: LY_healthy_y1_ag2 | C5: 18.811197 | D5: 18.830467 | E5: 18.84981 | F5: 18.869227 | G5: 18.885394 | H5: 18.901615 | I5: 18.91789 | J5: 18.934219 | K5: 18.950603 | L5: 18.964635 | M5: 18.978709 | N5: 18.992826 | O5: 19.006986 | P5: 19.021188 | Q5: 19.033727 | R5: 19.0463 | S5: 19.058909 | T5: 19.071553 | U5: 19.084233 | V5: 19.095437 | W5: 19.106672 | X5: 19.117938 | Y5: 19.129234 | Z5: 19.140562 | AA5: 19.150477 | AC5: LY_postTB_y1_ag2 | AD5: 18.671181 | AE5: 18.692386 | AF5: 18.713681 | AG5: 18.735065 | AH5: 18.752854 | AI5: 18.770708 | AJ5: 18.788628 | AK5: 18.806613 | AL5: 18.824665 | AM5: 18.84011 | AN5: 18.855606 | AO5: 18.871153 | AP5: 18.886752 | AQ5: 18.902402 | AR5: 18.916204 | AS5: 18.930049 | AT5: 18.943937 | AU5: 18.957867 | AV5: 18.97184 | AW5: 18.98416 | AX5: 18.996517 | AY5: 19.00891 | AZ5: 19.02134 | BA5: 19.033808 | BB5: 19.044697
B6: LY_healthy_y1_ag3 | C6: 18.418305 | D6: 18.441232 | E6: 18.464248 | F6: 18.487355 | G6: 18.506609 | H6: 18.525929 | I6: 18.545315 | J6: 18.564768 | K6: 18.584289 | L6: 18.601029 | M6: 18.617821 | N6: 18.634665 | O6: 18.651562 | P6: 18.668512 | Q6: 18.68349 | R6: 18.698511 | S6: 18.713576 | T6: 18.728684 | U6: 18.743837 | V6: 18.757261 | W6: 18.770722 | X6: 18.784221 | Y6: 18.797759 | Z6: 18.811336 | AA6: 18.823248 | AC6: LY_postTB_y1_ag3 | AD6: 18.249238 | AE6: 18.274427 | AF6: 18.299725 | AG6: 18.325133 | AH6: 18.346283 | AI6: 18.367514 | AJ6: 18.388825 | AK6: 18.410217 | AL6: 18.43169 | AM6: 18.450085 | AN6: 18.468543 | AO6: 18.487064 | AP6: 18.505648 | AQ6: 18.524296 | AR6: 18.540757 | AS6: 18.557269 | AT6: 18.573835 | AU6: 18.590453 | AV6: 18.607124 | AW6: 18.621859 | AX6: 18.636639 | AY6: 18.651465 | AZ6: 18.666337 | BA6: 18.681255 | BB6: 18.694314
B7: LY_healthy_y1_ag4 | C7: 17.923795 | D7: 17.95124 | E7: 17.978795 | F7: 18.00646 | G7: 18.029566 | H7: 18.052752 | I7: 18.076021 | J7: 18.099371 | K7: 18.122803 | L7: 18.142947 | M7: 18.163155 | N7: 18.183427 | O7: 18.203764 | P7: 18.224166 | Q7: 18.242226 | R7: 18.260339 | S7: 18.278506 | T7: 18.296728 | U7: 18.315004 | V7: 18.331247 | W7: 18.347537 | X7: 18.363875 | Y7: 18.380261 | Z7: 18.396694 | AA7: 18.411156 | AC7: LY_postTB_y1_ag4 | AD7: 17.718355 | AE7: 17.748467 | AF7: 17.778713 | AG7: 17.809094 | AH7: 17.834442 | AI7: 17.859888 | AJ7: 17.885432 | AK7: 17.911076 | AL7: 17.93682 | AM7: 17.958925 | AN7: 17.981108 | AO7: 18.003369 | AP7: 18.025708 | AQ7: 18.048125 | AR7: 18.067947 | AS7: 18.087832 | AT7: 18.107783 | AU7: 18.127799 | AV7: 18.14788 | AW7: 18.165687 | AX7: 18.18355 | AY7: 18.201469 | AZ7: 18.219445 | BA7: 18.237478 | BB7: 18.253312
B8: LY_healthy_y1_ag5 | C8: 17.348664 | D8: 17.380545 | E8: 17.412555 | F8: 17.444697 | G8: 17.471675 | H8: 17.498749 | I8: 17.52592 | J8: 17.553189 | K8: 17.580556 | L8: 17.604189 | M8: 17.627899 | N8: 17.651685 | O8: 17.67555 | P8: 17.699492 | Q8: 17.720761 | R8: 17.742095 | S8: 17.763494 | T8: 17.784958 | U8: 17.806488 | V8: 17.82573 | W8: 17.84503 | X8: 17.864387 | Y8: 17.883802 | Z8: 17.903275 | AA8: 17.920502 | AC8: LY_postTB_y1_ag5 | AD8: 17.103594 | AE8: 17.138513 | AF8: 17.17359 | AG8: 17.208825 | AH8: 17.23837 | AI8: 17.268032 | AJ8: 17.297811 | AK8: 17.327707 | AL8: 17.357722 | AM8: 17.383612 | AN8: 17.409595 | AO8: 17.435671 | AP8: 17.46184 | AQ8: 17.488103 | AR8: 17.511407 | AS8: 17.534789 | AT8: 17.558249 | AU8: 17.581787 | AV8: 17.605404 | AW8: 17.626462 | AX8: 17.647587 | AY8: 17.668781 | AZ8: 17.690044 | BA8: 17.711376 | BB8: 17.730205
B9: LY_healthy_y1_ag6 | C9: 16.706982 | D9: 16.742093 | E9: 16.777348 | F9: 16.812748 | G9: 16.84271 | H9: 16.872781 | I9: 16.902961 | J9: 16.933251 | K9: 16.963651 | L9: 16.990096 | M9: 17.016629 | N9: 17.04325 | O9: 17.069958 | P9: 17.096756 | Q9: 17.120713 | R9: 17.144743 | S9: 17.168849 | T9: 17.19303 | U9: 17.217286 | V9: 17.23916 | W9: 17.261101 | X9: 17.283109 | Y9: 17.305185 | Z9: 17.327329 | AA9: 17.347086 | AC9: LY_postTB_y1_ag6 | AD9: 16.422198 | AE9: 16.46056 | AF9: 16.499095 | AG9: 16.537806 | AH9: 16.570538 | AI9: 16.603401 | AJ9: 16.636394 | AK9: 16.66952 | AL9: 16.702778 | AM9: 16.731677 | AN9: 16.760681 | AO9: 16.78979 | AP9: 16.819005 | AQ9: 16.848327 | AR9: 16.874509 | AS9: 16.90078 | AT9: 16.92714 | AU9: 16.953591 | AV9: 16.980131 | AW9: 17.004006 | AX9: 17.02796 | AY9: 17.051993 | AZ9: 17.076107 | BA9: 17.100301 | BB9: 17.121838
B10: LY_healthy_y1_ag7 | C10: 16.008405 | D10: 16.044646 | E10: 16.081034 | F10: 16.117569 | G10: 16.148855 | H10: 16.180254 | I10: 16.211765 | J10: 16.243391 | K10: 16.275131 | L10: 16.303046 | M10: 16.331054 | N10: 16.359154 | O10: 16.387348 | P10: 16.415636 | Q10: 16.441172 | R10: 16.466787 | S10: 16.492483 | T10: 16.51826 | U10: 16.544119 | V10: 16.567757 | W10: 16.591469 | X10: 16.615256 | Y10: 16.639118 | Z10: 16.663055 | AA10: 16.684681 | AC10: LY_postTB_y1_ag7 | AD10: 15.686513 | AE10: 15.725974 | AF10: 15.765611 | AG10: 15.805425 | AH10: 15.839484 | AI10: 15.873677 | AJ10: 15.908006 | AK10: 15.942472 | AL10: 15.977074 | AM10: 16.00747 | AN10: 16.037977 | AO10: 16.068595 | AP10: 16.099324 | AQ10: 16.130165 | AR10: 16.157971 | AS10: 16.185873 | AT10: 16.21387 | AU10: 16.241963 | AV10: 16.270154 | AW10: 16.295856 | AX10: 16.321646 | AY10: 16.347524 | AZ10: 16.37349 | BA10: 16.399544 | BB10: 16.423027
B11: LY_healthy_y1_ag8 | C11: 15.265082 | D11: 15.299962 | E11: 15.334979 | F11: 15.370132 | G11: 15.400671 | H11: 15.431318 | I11: 15.462072 | J11: 15.492935 | K11: 15.523907 | L11: 15.551544 | M11: 15.579271 | N11: 15.607089 | O11: 15.634999 | P11: 15.663001 | Q11: 15.688625 | R11: 15.71433 | S11: 15.740116 | T11: 15.765984 | U11: 15.791933 | V11: 15.816102 | W11: 15.840348 | X11: 15.864672 | Y11: 15.889075 | Z11: 15.913556 | AA11: 15.936034 | AC11: LY_postTB_y1_ag8 | AD11: 14.911785 | AE11: 14.949592 | AF11: 14.98756 | AG11: 15.025691 | AH11: 15.058782 | AI11: 15.091999 | AJ11: 15.125345 | AK11: 15.158819 | AL11: 15.192422 | AM11: 15.22237 | AN11: 15.252425 | AO11: 15.282588 | AP11: 15.312858 | AQ11: 15.343237 | AR11: 15.371003 | AS11: 15.398863 | AT11: 15.426818 | AU11: 15.454869 | AV11: 15.483016 | AW11: 15.509159 | AX11: 15.535392 | AY11: 15.561716 | AZ11: 15.588131 | BA11: 15.614637 | BB11: 15.638915
B12: LY_healthy_y1_ag9 | C12: 14.470708 | D12: 14.502032 | E12: 14.533471 | F12: 14.565027 | G12: 14.592898 | H12: 14.620864 | I12: 14.648924 | J12: 14.677081 | K12: 14.705333 | L12: 14.73099 | M12: 14.75673 | N12: 14.782553 | O12: 14.808459 | P12: 14.834449 | Q12: 14.858658 | R12: 14.882943 | S12: 14.907305 | T12: 14.931743 | U12: 14.956257 | V12: 14.979674 | W12: 15.003167 | X12: 15.026737 | Y12: 15.050384 | Z12: 15.074109 | AA12: 15.096339 | AC12: LY_postTB_y1_ag9 | AD12: 14.093144 | AE12: 14.126879 | AF12: 14.16075 | AG12: 14.194759 | AH12: 14.22476 | AI12: 14.254871 | AJ12: 14.285094 | AK12: 14.315429 | AL12: 14.345876 | AM12: 14.373491 | AN12: 14.401202 | AO12: 14.42901 | AP12: 14.456915 | AQ12: 14.484917 | AR12: 14.51097 | AS12: 14.53711 | AT12: 14.563338 | AU12: 14.589655 | AV12: 14.616062 | AW12: 14.641211 | AX12: 14.666447 | AY12: 14.691772 | AZ12: 14.717185 | BA12: 14.742688 | BB12: 14.766522
B13: LY_healthy_y1_ag10 | C13: 13.566116 | D13: 13.59339 | E13: 13.62076 | F13: 13.648228 | G13: 13.672853 | H13: 13.69756 | I13: 13.722348 | J13: 13.747219 | K13: 13.772172 | L13: 13.795234 | M13: 13.81837 | N13: 13.841579 | O13: 13.864862 | P13: 13.88822 | Q13: 13.910387 | R13: 13.932625 | S13: 13.954932 | T13: 13.977309 | U13: 13.999757 | V13: 14.021852 | W13: 14.044021 | X13: 14.066264 | Y13: 14.088583 | Z13: 14.110976 | AA13: 14.132467 | AC13: LY_postTB_y1_ag10 | AD13: 13.167266 | AE13: 13.1964 | AF13: 13.225645 | AG13: 13.255002 | AH13: 13.281286 | AI13: 13.307662 | AJ13: 13.334132 | AK13: 13.360696 | AL13: 13.387355 | AM13: 13.411962 | AN13: 13.436653 | AO13: 13.461428 | AP13: 13.486287 | AQ13: 13.511231 | AR13: 13.534879 | AS13: 13.558606 | AT13: 13.582412 | AU13: 13.606299 | AV13: 13.630265 | AW13: 13.653785 | AX13: 13.677388 | AY13: 13.701075 | AZ13: 13.724846 | BA13: 13.748703 | BB13: 13.771541
B14: LY_healthy_y1_ag11 | C14: 12.529842 | D14: 12.553114 | E14: 12.576467 | F14: 12.599901 | G14: 12.621244 | H14: 12.642657 | I14: 12.66414 | J14: 12.685693 | K14: 12.707318 | L14: 12.727594 | M14: 12.747934 | N14: 12.76834 | O14: 12.788812 | P14: 12.809349 | Q14: 12.829179 | R14: 12.849072 | S14: 12.869029 | T14: 12.88905 | U14: 12.909135 | V14: 12.929549 | W14: 12.950034 | X14: 12.97059 | Y14: 12.991219 | Z14: 13.01192 | AA14: 13.032323 | AC14: LY_postTB_y1_ag11 | AD14: 12.113289 | AE14: 12.137889 | AF14: 12.162579 | AG14: 12.18736 | AH14: 12.209894 | AI14: 12.232507 | AJ14: 12.255199 | AK14: 12.27797 | AL14: 12.30082 | AM14: 12.322215 | AN14: 12.343682 | AO14: 12.365222 | AP14: 12.386836 | AQ14: 12.408522 | AR14: 12.429444 | AS14: 12.450436 | AT14: 12.471499 | AU14: 12.492632 | AV14: 12.513838 | AW14: 12.53533 | AX14: 12.556902 | AY14: 12.578552 | AZ14: 12.600282 | BA14: 12.622092 | BB14: 12.643542
B15: LY_healthy_y1_ag12 | C15: 11.334561 | D15: 11.354288 | E15: 11.374084 | F15: 11.393948 | G15: 11.412428 | H15: 11.430969 | I15: 11.449571 | J15: 11.468236 | K15: 11.486964 | L15: 11.504779 | M15: 11.522653 | N15: 11.540586 | O15: 11.558579 | P15: 11.576631 | Q15: 11.594247 | R15: 11.611922 | S15: 11.629655 | T15: 11.647447 | U15: 11.665298 | V15: 11.683997 | W15: 11.702764 | X15: 11.721601 | Y15: 11.740507 | Z15: 11.759484 | AA15: 11.778662 | AC15: LY_postTB_y1_ag12 | AD15: 10.904145 | AE15: 10.924723 | AF15: 10.945375 | AG15: 10.966103 | AH15: 10.985359 | AI15: 11.004682 | AJ15: 11.024073 | AK15: 11.043532 | AL15: 11.063059 | AM15: 11.081607 | AN15: 11.100219 | AO15: 11.118895 | AP15: 11.137636 | AQ15: 11.156443 | AR15: 11.174779 | AS15: 11.19318 | AT15: 11.211643 | AU15: 11.230172 | AV15: 11.248764 | AW15: 11.268193 | AX15: 11.287697 | AY15: 11.307275 | AZ15: 11.326929 | BA15: 11.346658 | BB15: 11.366566
... B19: LY_healthy_y1_ag16 | C19: 4.7075712 | D19: 4.7178093 | E19: 4.7280943 | F19: 4.7384265 | G19: 4.7489086 | H19: 4.7594397 | I19: 4.7700201 | J19: 4.7806502 | K19: 4.7913305 | L19: 4.8020505 | M19: 4.8128227 | N19: 4.8236474 | O19: 4.8345251 | P19: 4.8454562 | Q19: 4.856266 | R19: 4.8671293 | S19: 4.8780465 | T19: 4.889018 | U19: 4.9000443 | V19: 4.9125136 | W19: 4.9250527 | X19: 4.9376623 | Y19: 4.950343 | Z19: 4.9630955 | AA19: 4.9767284 | AC19: LY_postTB_y1_ag16 | AD19: 4.3425472 | AE19: 4.3524178 | AF19: 4.3623346 | AG19: 4.3722979 | AH19: 4.382406 | AI19: 4.3925624 | AJ19: 4.4027673 | AK19: 4.4130213 | AL19: 4.4233246 | AM19: 4.4336451 | AN19: 4.4440169 | AO19: 4.4544402 | AP19: 4.4649156 | AQ19: 4.4754434 | AR19: 4.4858425 | AS19: 4.4962938 | AT19: 4.5067979 | AU19: 4.5173552 | AV19: 4.5279662 | AW19: 4.5399786 | AX19: 4.5520596 | AY19: 4.5642096 | AZ19: 4.5764294 | BA19: 4.5887197 | BB19: 4.6018671
B20: LY_healthy_y2_ag1 | C20: =D4*(1+disc)^-1 -> 18.169725 | AC20: LY_postTB_y2_ag1 | AD20: =AE4*(1+disc)^-1 -> 18.052346
B21: LY_healthy_y2_ag2 | C21: =D5*(1+disc)^-1 -> 17.933778 | AC21: LY_postTB_y2_ag2 | AD21: =AE5*(1+disc)^-1 -> 17.802273
B22: LY_healthy_y2_ag3 | C22: =D6*(1+disc)^-1 -> 17.563078 | AC22: LY_postTB_y2_ag3 | AD22: =AE6*(1+disc)^-1 -> 17.404216
B23: LY_healthy_y2_ag4 | C23: =D7*(1+disc)^-1 -> 17.096419 | AC23: LY_postTB_y2_ag4 | AD23: =AE7*(1+disc)^-1 -> 16.903302
B24: LY_healthy_y2_ag5 | C24: =D8*(1+disc)^-1 -> 16.5529 | AC24: LY_postTB_y2_ag5 | AD24: =AE8*(1+disc)^-1 -> 16.322393
B25: LY_healthy_y2_ag6 | C25: =D9*(1+disc)^-1 -> 15.94485 | AC25: LY_postTB_y2_ag6 | AD25: =AE9*(1+disc)^-1 -> 15.676723
B26: LY_healthy_y2_ag7 | C26: =D10*(1+disc)^-1 -> 15.280615 | AC26: LY_postTB_y2_ag7 | AD26: =AE10*(1+disc)^-1 -> 14.977118
B27: LY_healthy_y2_ag8 | C27: =D11*(1+disc)^-1 -> 14.571393 | AC27: LY_postTB_y2_ag8 | AD27: =AE11*(1+disc)^-1 -> 14.237706
B28: LY_healthy_y2_ag9 | C28: =D12*(1+disc)^-1 -> 13.811459 | AC28: LY_postTB_y2_ag9 | AD28: =AE12*(1+disc)^-1 -> 13.45417
B29: LY_healthy_y2_ag10 | C29: =D13*(1+disc)^-1 -> 12.946085 | AC29: LY_postTB_y2_ag10 | AD29: =AE13*(1+disc)^-1 -> 12.568
B30: LY_healthy_y2_ag11 | C30: =D14*(1+disc)^-1 -> 11.955347 | AC30: LY_postTB_y2_ag11 | AD30: =AE14*(1+disc)^-1 -> 11.559894
B31: LY_healthy_y2_ag12 | C31: =D15*(1+disc)^-1 -> 10.813608 | AC31: LY_postTB_y2_ag12 | AD31: =AE15*(1+disc)^-1 -> 10.404498
... B35: LY_healthy_y2_ag16 | C35: =D19*(1+disc)^-1 -> 4.4931517 | AC35: LY_postTB_y2_ag16 | AD35: =AE19*(1+disc)^-1 -> 4.1451598
B36: LY_healthy_y3_ag1 | C36: =E4*(1+disc)^-2 -> 17.320414 | AC36: LY_postTB_y3_ag1 | AD36: =AF4*(1+disc)^-2 -> 17.210286
B37: LY_healthy_y3_ag2 | C37: =E5*(1+disc)^-2 -> 17.097333 | AC37: LY_postTB_y3_ag2 | AD37: =AF5*(1+disc)^-2 -> 16.97386
B38: LY_healthy_y3_ag3 | C38: =E6*(1+disc)^-2 -> 16.747617 | AC38: LY_postTB_y3_ag3 | AD38: =AF6*(1+disc)^-2 -> 16.59839
B39: LY_healthy_y3_ag4 | C39: =E7*(1+disc)^-2 -> 16.307297 | AC39: LY_postTB_y3_ag4 | AD39: =AF7*(1+disc)^-2 -> 16.125817
B40: LY_healthy_y3_ag5 | C40: =E8*(1+disc)^-2 -> 15.793701 | AC40: LY_postTB_y3_ag5 | AD40: =AF8*(1+disc)^-2 -> 15.576952
B41: LY_healthy_y3_ag6 | C41: =E9*(1+disc)^-2 -> 15.217549 | AC41: LY_postTB_y3_ag6 | AD41: =AF9*(1+disc)^-2 -> 14.965166
B42: LY_healthy_y3_ag7 | C42: =E10*(1+disc)^-2 -> 14.585972 | AC42: LY_postTB_y3_ag7 | AD42: =AF10*(1+disc)^-2 -> 14.299874
B43: LY_healthy_y3_ag8 | C43: =E11*(1+disc)^-2 -> 13.909278 | AC43: LY_postTB_y3_ag8 | AD43: =AF11*(1+disc)^-2 -> 13.594159
B44: LY_healthy_y3_ag9 | C44: =E12*(1+disc)^-2 -> 13.182287 | AC44: LY_postTB_y3_ag9 | AD44: =AF12*(1+disc)^-2 -> 12.844218
B45: LY_healthy_y3_ag10 | C45: =E13*(1+disc)^-2 -> 12.354431 | AC45: LY_postTB_y3_ag10 | AD45: =AF13*(1+disc)^-2 -> 11.99605
B46: LY_healthy_y3_ag11 | C46: =E14*(1+disc)^-2 -> 11.407227 | AC46: LY_postTB_y3_ag11 | AD46: =AF14*(1+disc)^-2 -> 11.031817
...
